Workbook

Sheet PMMOQP

Sheet 封面
B1: 索引页
C4: 资 产 评 估 申 报 表
D5: 企业填写以下内容
D7: 被评估单位： | Q7: 评估对象是企业整体资产时，为被评估企业，评估对象是单项资产时，为产权持有单位
D9: 评估基准日： | G9: 年 | I9: 月 | K9: 日
D11: 被评估单位填表人： | Q11: 同第一行
D13: 填表日期： | G13: 年 | I13: 月 | K13: 日
D15: 评估机构填写以下内容
D16: 项目负责人：
D18: 签字注册资产评估师：
D20: 流动资产评估人员：
D22: 长期投资评估人员：
D24: 房 屋 类评估人员：
D26: 设 备 类评估人员：
D28: 土 地评估人员：
D30: 生物资产评估人员：
D32: 油气资产评估人员：
D34: 其他无形评估人员：
D36: 其他资产评估人员：
D38: 负 债类评估人员：

Sheet 索引目录
A1: 资产评估申报表索引目录
B2: 评估申报表封面
B3: 评估申报表说明（填表前请先阅读）
B4: 基本情况表 | C4: 资产负债表 | D4: 汇总表 | E4: 分类汇总表
C6: 流动资产 | D6: 货币资金 | E6: 现金 | G6: 流动负债 | I6: 短期借款
E7: 银行存款 | I7: 交易性金融负债
E8: 其他货币资金 | I8: 应付票据
D9: 交易性金融资产 | E9: 股票投资 | I9: 应付账款
E10: 债券投资 | I10: 预收款项
E11: 基金投资 | I11: 应付职工薪酬
D12: 应收票据 | I12: 应交税费
D13: 应收账款 | I13: 应付利息
D14: 预付账款 | I14: 应付股利（应付利润）
D15: 应收利息 | I15: 其他应付款
D16: 应收股利 | I16: 一年内到期的非流动负债
D17: 其他应收款 | I17: 其他流动负债
D18: 存货 | E18: 材料采购（在途物资）
E19: 原材料
E20: 在库周转材料 | G20: 非流动负债 | I20: 长期借款
E21: 委托加工物资 | I21: 应付债券
E22: 产成品（库存商品） | I22: 长期应付款
E23: 在产品（自制半成品） | I23: 专项应付款
E24: 发出商品 | I24: 预计负债
E25: 在用周转材料 | I25: 递延所得税负债
D26: 一年到期非流动资产 | I26: 其他非流动负债
D27: 其他流动资产
C28: 长期投资 | D28: 可供出售金融资产 | E28: 股票投资
E29: 债券投资
E30: 其他投资
D31: 持有至到期投资
D32: 长期应收款
D33: 长期股权投资
D34: 投资性房地产
C35: 固定资产 | D35: 固定资产 | E35: 房屋建筑物
E36: 构筑物及其他辅助设施
E37: 管道及沟槽
E38: 机器设备
E39: 车辆
E40: 电子设备
E41: 土地
...

Sheet 填表说明
A1: 评估申报表填表说明
A2: 返回索引页
A3: 1、 | B3: 本工作簿用于资产评估委托方或资产占有方对评估基准日下的委估资产及负债的账面价值的申报；
B4: 请贵单位填表人员按要求对工作表中账面价值及其以左各栏次或项目据实填写
B5: （此外，应收账款、其他应收款还需要填写账龄分析内容）；
A6: 2、 | B6: 此表各科目明细的合计数，应与本次资产评估范围内的资产评估基准日的资产负债表的数据相符；
A7: 3、 | B7: 如有债权、债务性资产的未达、坏账及实物性资产的毁损、报废等的项目应在其备注中说明；
A8: 4、 | B8: 明细表中如有日期档，除各明细表中有具体要求外，其格式应为“XXXX-XX”；
B9: 例：“2000年09月10日”应填为“2000-09”
B10: 如无法确定具体月份，请将月份填为01月；
B11: 例：“2000年”应填为“2000-01”
B12: 如为累计发生的业务，请将发生日期填为最后一笔业务的发生日期；
A13: 5、 | B13: 如明细表的行数不够时，请填表人员在“合计”的上两行进行插入行。
A14: 6、 | B14: 填表人可通过“资产评估申报表索引目录”来选择要查看或修改的科目,通过“返回索引页”按纽可返回“选择目录”
A15: 7、 | B15: 填表人可通过点击各汇总表中的“科目名称”进入各明细表，再通过点击各工作表左上角的“返回”来返回上一级汇总表。
A16: 注： | B16: 除以上要求企业填写的或按具体情况评估人员另作要求填写的栏目或项外，企业不应对此套表的其它部分
B17: 作任何修改变动，谢谢合作！
A19: 核心提示：不适用的工作表可以隐藏，但不可删除！
C20: 工作表标签不能更改！
B22: 如有疑问请与我公司项目组或我公司现场人员联系
B23: 公司电话：010-68365066 传真：010-68365038

Sheet 资产负债表
A1: 返回索引页
A2: 资产负债表
A3: =CONCATENATE(封面!F9,封面!G9,封面!H9,封面!I9,封面!J9,封面!K9)
A4: ="编制单位:"&封面!F7 | J4: 金额单位：人民币元
A5: 资产 | B5: 序号 | C5: 期初数 | D5: 期末数 | E5: 备注 | F5: 负债及所有者权益 | G5: 序号 | H5: 期初数 | I5: 期末数 | J5: 备注
A6: 流动资产： | B6: 1 | F6: 流动负债： | G6: 34
A7: 货币资金 | B7: 2 | F7: 短期借款 | G7: 35
A8: 交易性金融资产 | B8: 3 | F8: 交易性金融负债 | G8: 36
A9: 应收票据 | B9: 4 | F9: 应付票据 | G9: 37
A10: 应收账款 | B10: 5 | F10: 应付账款 | G10: 38
A11: 预付款项 | B11: 6 | F11: 预收款项 | G11: 39
A12: 应收利息 | B12: 7 | F12: 应付职工薪酬 | G12: 40
A13: 应收股利 | B13: 8 | F13: 应交税费 | G13: 41
A14: 其他应收款 | B14: 9 | F14: 应付利息 | G14: 42
A15: 存货 | B15: 10 | F15: 应付股利 | G15: 43
A16: 一年内到期的非流动资产 | B16: 11 | F16: 其他应付款 | G16: 44
A17: 其他流动资产 | B17: 12 | F17: 一年内到期的非流动负债 | G17: 45
A18: 流动资产合计 | B18: 13 | C18: =SUM(C7:C17) | D18: =SUM(D7:D17) | F18: 其他流动负债 | G18: 46
A19: 非流动资产： | B19: 14 | F19: 流动负债合计 | G19: 47 | H19: =SUM(H7:H18) | I19: =SUM(I7:I18)
A20: 可供出售金融资产 | B20: 15 | F20: 非流动负债： | G20: 48
A21: 持有至到期投资 | B21: 16 | F21: 长期借款 | G21: 49
A22: 长期应收款 | B22: 17 | F22: 应付债券 | G22: 50
A23: 长期股权投资 | B23: 18 | C23: =D23 | F23: 长期应付款 | G23: 51
A24: 投资性房地产 | B24: 19 | F24: 专项应付款 | G24: 52
A25: 固定资产 | B25: 20 | F25: 预计负债 | G25: 53
A26: 在建工程 | B26: 21 | F26: 递延所得税负债 | G26: 54
A27: 工程物资 | B27: 22 | F27: 其他非流动负债 | G27: 55
A28: 固定资产清理 | B28: 23 | F28: 非流动负债合计 | G28: 56 | H28: =SUM(H21:H27) | I28: =SUM(I21:I27)
A29: 生产性生物资产 | B29: 24 | F29: 负债合计 | G29: 57 | H29: =H19+H28 | I29: =I19+I28
A30: 油气资产 | B30: 25 | F30: 所有者权益： | G30: 58
A31: 无形资产 | B31: 26 | F31: 实收资本 | G31: 59 | I31: =H31
A32: 开发支出 | B32: 27 | F32: 资本公积 | G32: 60 | I32: =H32
A33: 商誉 | B33: 28 | F33: 减：库存股 | G33: 61
A34: 长期待摊费用 | B34: 29 | F34: 盈余公积 | G34: 62
A35: 递延所得税资产 | B35: 30 | F35: 未分配利润 | G35: 63
A36: 其他非流动资产 | B36: 31 | F36: 所有者权益合计 | G36: 64 | H36: =SUM(H31,H32,H34,H35) | I36: =SUM(I31,I32,I34,I35)
A37: 非流动资产合计 | B37: 32 | C37: =SUM(C20:C36) | D37: =SUM(D20:D36)
A38: 资产总计 | B38: 33 | C38: =SUM(C37,C18) | D38: =SUM(D37,D18) | F38: 负债及所有者权益合计 | G38: 65 | H38: =H29+H36 | I38: =I29+I36
F39: 与总资产相差 | G39: 66 | H39: =H38-C38 | I39: =I38-D38
C40: 填表人： | E40: 财务主管： | H40: 负责人：

Sheet 汇总表
A1: 返回索引页
A2: 资 产 评 估 结 果 汇 总 表
A3: =CONCATENATE(封面!D9,封面!F9,封面!G9,封面!H9,封面!I9,封面!J9,封面!K9)
A4: =封面!D7&封面!F7 | G4: 金额单位：人民币元
A5: 项 目 | C5: 审计前账面值 | D5: 账面价值 | E5: 评估价值 | F5: 增减值 | G5: 增值率％
C6: A | D6: B | E6: C | F6: D=C-B | G6: E=D/B×100%
A7: 1 | B7: 流动资产 | C7: =分类汇总!C6/10000 | D7: =分类汇总!E6/10000 | E7: =分类汇总!F6/10000 | F7: =E7-D7 | G7: =IF(D7=0,"",F7/ABS(D7)*100)
A8: 2 | B8: 非流动资产 | C8: =分类汇总!C19/10000 | D8: =分类汇总!E19/10000 | E8: =分类汇总!F19/10000 | F8: =E8-D8 | G8: =IF(D8=0,"",F8/ABS(D8)*100)
B9: 可供出售金融资产 | C9: =分类汇总!C20/10000 | D9: =分类汇总!E20/10000 | E9: =分类汇总!F20/10000 | F9: =E9-D9 | G9: =IF(D9=0,"",F9/ABS(D9)*100)
B10: 持有至到期投资 | C10: =分类汇总!C21/10000 | D10: =分类汇总!E21/10000 | E10: =分类汇总!F21/10000 | F10: =E10-D10 | G10: =IF(D10=0,"",F10/ABS(D10)*100)
A11: 3 | B11: 其中：长期应收款 | C11: =分类汇总!C22/10000 | D11: =分类汇总!E22/10000 | E11: =分类汇总!F22/10000 | F11: =E11-D11 | G11: =IF(D11=0,"",F11/ABS(D11)*100)
A12: 4 | B12: 长期股权投资 | C12: =分类汇总!C23/10000 | D12: =分类汇总!E23 | E12: =分类汇总!F23 | F12: =E12-D12 | G12: =IF(D12=0,"",F12/ABS(D12)*100)
A13: 5 | B13: 投资性房地产 | C13: =分类汇总!C24/10000 | D13: =分类汇总!E24/10000 | E13: =分类汇总!F24/10000 | F13: =E13-D13 | G13: =IF(D13=0,"",F13/ABS(D13)*100)
A14: 6 | B14: 固定资产 | C14: =分类汇总!C25/10000 | D14: =分类汇总!E25/10000 | E14: =分类汇总!F25/10000 | F14: =E14-D14 | G14: =IF(D14=0,"",F14/ABS(D14)*100)
A15: 7 | B15: 其中：建 筑 物 | C15: =固定资产汇总!D7/10000 | D15: =固定资产汇总!F7/10000 | E15: =固定资产汇总!H7/10000 | F15: =E15-D15 | G15: =IF(D15=0,"",F15/ABS(D15)*100)
A16: 8 | B16: 设 备 | C16: =固定资产汇总!D13/10000 | D16: =固定资产汇总!F13/10000 | E16: =固定资产汇总!H13/10000 | F16: =E16-D16 | G16: =IF(D16=0,"",F16/ABS(D16)*100)
A17: 9 | B17: 土 地 | C17: =固定资产汇总!D19/10000 | D17: =固定资产汇总!F19/10000 | E17: =固定资产汇总!H19/10000 | F17: =E17-D17 | G17: =IF(D17=0,"",F17/ABS(D17)*100)
A18: 7 | B18: 在建工程 | C18: =分类汇总!C26/10000 | D18: =分类汇总!E26/10000 | E18: =分类汇总!F26/10000 | F18: =E18-D18 | G18: =IF(D18=0,"",F18/ABS(D18)*100)
A19: 8 | B19: 工程物资 | C19: =分类汇总!C27/10000 | D19: =分类汇总!E27/10000 | E19: =分类汇总!F27/10000 | F19: =E19-D19 | G19: =IF(D19=0,"",F19/ABS(D19)*100)
A20: 9 | B20: 固定资产清理 | C20: =分类汇总!C28/10000 | D20: =分类汇总!E28/10000 | E20: =分类汇总!F28/10000 | F20: =E20-D20 | G20: =IF(D20=0,"",F20/ABS(D20)*100)
A21: 10 | B21: 生产性生物资产 | C21: =分类汇总!C29/10000 | D21: =分类汇总!E29/10000 | E21: =分类汇总!F29/10000 | F21: =E21-D21 | G21: =IF(D21=0,"",F21/ABS(D21)*100)
A22: 11 | B22: 油气资产 | C22: =分类汇总!C30/10000 | D22: =分类汇总!E30/10000 | E22: =分类汇总!F30/10000 | F22: =E22-D22 | G22: =IF(D22=0,"",F22/ABS(D22)*100)
A23: 12 | B23: 无形资产 | C23: =分类汇总!C31/10000 | D23: =分类汇总!E31/10000 | E23: =分类汇总!F31/10000 | F23: =E23-D23 | G23: =IF(D23=0,"",F23/ABS(D23)*100)
A24: 13 | B24: 其中：土地使用权 | C24: =无形资产汇总!C6/10000 | D24: =无形资产汇总!D6/10000 | E24: =无形资产汇总!E6/10000 | F24: =E24-D24 | G24: =IF(D24=0,"",F24/ABS(D24)*100)
A25: 17 | B25: 开发支出 | C25: =分类汇总!C32/10000 | D25: =分类汇总!E32/10000 | E25: =分类汇总!F32/10000 | F25: =E25-D25 | G25: =IF(D25=0,"",F25/ABS(D25)*100)
A26: 18 | B26: 商誉 | C26: =分类汇总!C33/10000 | D26: =分类汇总!E33/10000 | E26: =分类汇总!F33/10000 | F26: =E26-D26 | G26: =IF(D26=0,"",F26/ABS(D26)*100)
A27: 19 | B27: 长期待摊费用 | C27: =分类汇总!C34/10000 | D27: =分类汇总!E34/10000 | E27: =分类汇总!F34/10000 | F27: =E27-D27 | G27: =IF(D27=0,"",F27/ABS(D27)*100)
A28: 20 | B28: 递延所得税资产 | C28: =分类汇总!C35/10000 | D28: =分类汇总!E35/10000 | E28: =分类汇总!F35/10000 | F28: =E28-D28 | G28: =IF(D28=0,"",F28/ABS(D28)*100)
A29: 13 | B29: 其他非流动资产 | C29: =分类汇总!C36/10000 | D29: =分类汇总!E36/10000 | E29: =分类汇总!F36/10000 | F29: =E29-D29 | G29: =IF(D29=0,"",F29/ABS(D29)*100)
A30: 14 | B30: 资产总计 | C30: =SUM(C7,C8) | D30: =SUM(D7,D8) | E30: =SUM(E7,E8) | F30: =SUM(F7,F8) | G30: =IF(D30=0,"",F30/ABS(D30)*100)
A31: 15 | B31: 流动负债 | C31: =分类汇总!C39/10000 | D31: =分类汇总!E39/10000 | E31: =分类汇总!F39/10000 | F31: =E31-D31 | G31: =IF(D31=0,"",F31/ABS(D31)*100)
A32: 16 | B32: 非流动负债 | C32: =分类汇总!C53/10000 | D32: =分类汇总!E53/10000 | E32: =分类汇总!F53/10000 | F32: =E32-D32 | G32: =IF(D32=0,"",F32/ABS(D32)*100)
A33: 17 | B33: 负债总计 | C33: =SUM(C31:C32) | D33: =SUM(D31:D32) | E33: =SUM(E31:E32) | F33: =SUM(F31:F32) | G33: =IF(D33=0,"",F33/ABS(D33)*100)
A34: 18 | B34: 净 资 产（所有者权益） | C34: =C30-C33 | D34: =D30-D33 | E34: =E30-E33 | F34: =F30-F33 | G34: =IF(D34=0,"",F34/ABS(D34)*100)
E35: 评估机构：中立国际房地产土地资产评估有限公司

Sheet 分类汇总
A1: 返回索引页 | B1: 返回
A2: 资产评估结果分类汇总表
A3: =CONCATENATE(封面!D9,封面!F9,封面!G9,封面!H9,封面!I9,封面!J9,封面!K9)
A4: =封面!D7&封面!F7 | H4: 金额单位：人民币元 | J4: =IF(COUNTIF(J6:J91,">0")+COUNTIF(J6:J91,"<0")>0,"出错","OK")
A5: 序号 | B5: 科目名称 | C5: 审计前账面值 | D5: 账面调整值 | E5: 账面价值 | F5: 评估价值 | G5: 增值额 | H5: 增值率% | I5: 企业报表数 | J5: 差异
A6: 1 | B6: 一、流动资产合计 | C6: =SUM(C7:C17) | D6: =SUM(D7:D17) | E6: =SUM(E7:E17) | F6: =SUM(F7:F17) | G6: =SUM(G7:G17) | H6: =IF(E6=0,"",G6/ABS(E6)*100) | I6: =资产负债表!D18 | J6: =ROUND(E6-I6,2)
A7: 2 | B7: 货币资金 | C7: =流动汇总!E6 | D7: =E7-C7 | E7: =流动汇总!F6 | F7: =流动汇总!G6 | G7: =F7-E7 | H7: =IF(E7=0,"",G7/ABS(E7)*100) | I7: =资产负债表!D7 | J7: =ROUND(E7-I7,2)
A8: 3 | B8: 交易性金融资产 | C8: =流动汇总!E7 | D8: =E8-C8 | E8: =流动汇总!F7 | F8: =流动汇总!G7 | G8: =F8-E8 | H8: =IF(E8=0,"",G8/ABS(E8)*100) | I8: =资产负债表!D8 | J8: =ROUND(E8-I8,2)
A9: 4 | B9: 应收票据 | C9: =流动汇总!E8 | D9: =E9-C9 | E9: =流动汇总!F8 | F9: =流动汇总!G8 | G9: =F9-E9 | H9: =IF(E9=0,"",G9/ABS(E9)*100) | I9: =资产负债表!D9 | J9: =ROUND(E9-I9,2)
A10: 5 | B10: 应收账款 | C10: =流动汇总!E9 | D10: =E10-C10 | E10: =流动汇总!F9 | F10: =流动汇总!G9 | G10: =F10-E10 | H10: =IF(E10=0,"",G10/ABS(E10)*100) | I10: =资产负债表!D10 | J10: =ROUND(E10-I10,2)
A11: 6 | B11: 预付款项 | C11: =流动汇总!E10 | D11: =E11-C11 | E11: =流动汇总!F10 | F11: =流动汇总!G10 | G11: =F11-E11 | H11: =IF(E11=0,"",G11/ABS(E11)*100) | I11: =资产负债表!D11 | J11: =ROUND(E11-I11,2)
A12: 7 | B12: 应收利息 | C12: =流动汇总!E11 | D12: =E12-C12 | E12: =流动汇总!F11 | F12: =流动汇总!G11 | G12: =F12-E12 | H12: =IF(E12=0,"",G12/ABS(E12)*100) | I12: =资产负债表!D12 | J12: =ROUND(E12-I12,2)
A13: 8 | B13: 应收股利 | C13: =流动汇总!E12 | D13: =E13-C13 | E13: =流动汇总!F12 | F13: =流动汇总!G12 | G13: =F13-E13 | H13: =IF(E13=0,"",G13/ABS(E13)*100) | I13: =资产负债表!D13 | J13: =ROUND(E13-I13,2)
A14: 9 | B14: 其他应收款 | C14: =流动汇总!E13 | D14: =E14-C14 | E14: =流动汇总!F13 | F14: =流动汇总!G13 | G14: =F14-E14 | H14: =IF(E14=0,"",G14/ABS(E14)*100) | I14: =资产负债表!D14 | J14: =ROUND(E14-I14,2)
A15: 10 | B15: 存货 | C15: =流动汇总!E14 | D15: =E15-C15 | E15: =流动汇总!F14 | F15: =流动汇总!G14 | G15: =F15-E15 | H15: =IF(E15=0,"",G15/ABS(E15)*100) | I15: =资产负债表!D15 | J15: =ROUND(E15-I15,2)
A16: 11 | B16: 一年内到期的非流动资产 | C16: =流动汇总!E15 | D16: =E16-C16 | E16: =流动汇总!F15 | F16: =流动汇总!G15 | G16: =F16-E16 | H16: =IF(E16=0,"",G16/ABS(E16)*100) | I16: =资产负债表!D16 | J16: =ROUND(E16-I16,2)
A17: 12 | B17: 其他流动资产 | C17: =流动汇总!E16 | D17: =E17-C17 | E17: =流动汇总!F16 | F17: =流动汇总!G16 | G17: =F17-E17 | H17: =IF(E17=0,"",G17/ABS(E17)*100) | I17: =资产负债表!D17 | J17: =ROUND(E17-I17,2)
A18: 13 | H18: =IF(E18=0,"",G18/ABS(E18)*100) | J18: =ROUND(E18-I18,2)
A19: 14 | B19: 二、非流动资产合计 | C19: =SUM(C20:C36) | D19: =SUM(D20:D36) | E19: =SUM(E20:E36) | F19: =SUM(F20:F36) | G19: =SUM(G20:G36) | H19: =IF(E19=0,"",G19/ABS(E19)*100) | I19: =资产负债表!D37 | J19: =ROUND(E19-I19,2)
A20: 15 | B20: 可供出售金融资产 | C20: =非流动资产汇总!C6 | D20: =E20-C20 | E20: =非流动资产汇总!D6 | F20: =非流动资产汇总!E6 | G20: =F20-E20 | H20: =IF(E20=0,"",G20/ABS(E20)*100) | I20: =资产负债表!D20 | J20: =ROUND(E20-I20,2)
A21: 16 | B21: 持有至到期投资 | C21: =非流动资产汇总!C7 | D21: =E21-C21 | E21: =非流动资产汇总!D7 | F21: =非流动资产汇总!E7 | G21: =F21-E21 | H21: =IF(E21=0,"",G21/ABS(E21)*100) | I21: =资产负债表!D21 | J21: =ROUND(E21-I21,2)
A22: 17 | B22: 长期应收款 | C22: =非流动资产汇总!C8 | D22: =E22-C22 | E22: =非流动资产汇总!D8 | F22: =非流动资产汇总!E8 | G22: =F22-E22 | H22: =IF(E22=0,"",G22/ABS(E22)*100) | I22: =资产负债表!D22 | J22: =ROUND(E22-I22,2)
A23: 18 | B23: 长期股权投资 | C23: =非流动资产汇总!C9 | D23: =E23-C23 | E23: =非流动资产汇总!D9 | F23: =非流动资产汇总!E9 | G23: =F23-E23 | H23: =IF(E23=0,"",G23/ABS(E23)*100) | I23: =资产负债表!D23 | J23: =ROUND(E23-I23,2)
A24: 19 | B24: 投资性房地产 | C24: =非流动资产汇总!C10 | D24: =E24-C24 | E24: =非流动资产汇总!D10 | F24: =非流动资产汇总!E10 | G24: =F24-E24 | H24: =IF(E24=0,"",G24/ABS(E24)*100) | I24: =资产负债表!D24 | J24: =ROUND(E24-I24,2)
A25: 20 | B25: 固定资产 | C25: =非流动资产汇总!C11 | D25: =E25-C25 | E25: =非流动资产汇总!D11 | F25: =非流动资产汇总!E11 | G25: =F25-E25 | H25: =IF(E25=0,"",G25/ABS(E25)*100) | I25: =资产负债表!D25 | J25: =ROUND(E25-I25,2)
A26: 21 | B26: 在建工程 | C26: =非流动资产汇总!C12 | D26: =E26-C26 | E26: =非流动资产汇总!D12 | F26: =非流动资产汇总!E12 | G26: =F26-E26 | H26: =IF(E26=0,"",G26/ABS(E26)*100) | I26: =资产负债表!D26 | J26: =ROUND(E26-I26,2)
A27: 22 | B27: 工程物资 | C27: =非流动资产汇总!C13 | D27: =E27-C27 | E27: =非流动资产汇总!D13 | F27: =非流动资产汇总!E13 | G27: =F27-E27 | H27: =IF(E27=0,"",G27/ABS(E27)*100) | I27: =资产负债表!D27 | J27: =ROUND(E27-I27,2)
A28: 23 | B28: 固定资产清理 | C28: =非流动资产汇总!C14 | D28: =E28-C28 | E28: =非流动资产汇总!D14 | F28: =非流动资产汇总!E14 | G28: =F28-E28 | H28: =IF(E28=0,"",G28/ABS(E28)*100) | I28: =资产负债表!D28 | J28: =ROUND(E28-I28,2)
A29: 24 | B29: 生产性生物资产 | C29: =非流动资产汇总!C15 | D29: =E29-C29 | E29: =非流动资产汇总!D15 | F29: =非流动资产汇总!E15 | G29: =F29-E29 | H29: =IF(E29=0,"",G29/ABS(E29)*100) | I29: =资产负债表!D29 | J29: =ROUND(E29-I29,2)
A30: 25 | B30: 油气资产 | C30: =非流动资产汇总!C16 | D30: =E30-C30 | E30: =非流动资产汇总!D16 | F30: =非流动资产汇总!E16 | G30: =F30-E30 | H30: =IF(E30=0,"",G30/ABS(E30)*100) | I30: =资产负债表!D30 | J30: =ROUND(E30-I30,2)
A31: 26 | B31: 无形资产 | C31: =非流动资产汇总!C18 | D31: =E31-C31 | E31: =非流动资产汇总!D18 | F31: =非流动资产汇总!E18 | G31: =F31-E31 | H31: =IF(E31=0,"",G31/ABS(E31)*100) | I31: =资产负债表!D31 | J31: =ROUND(E31-I31,2)
A32: 27 | B32: 开发支出 | C32: =非流动资产汇总!C19 | D32: =E32-C32 | E32: =非流动资产汇总!D19 | F32: =非流动资产汇总!E19 | G32: =F32-E32 | H32: =IF(E32=0,"",G32/ABS(E32)*100) | I32: =资产负债表!D32 | J32: =ROUND(E32-I32,2)
A33: 28 | B33: 商誉 | C33: =非流动资产汇总!C20 | D33: =E33-C33 | E33: =非流动资产汇总!D20 | F33: =非流动资产汇总!E20 | G33: =F33-E33 | H33: =IF(E33=0,"",G33/ABS(E33)*100) | I33: =资产负债表!D33 | J33: =ROUND(E33-I33,2)
A34: 29 | B34: 长期待摊费用 | C34: =非流动资产汇总!C21 | D34: =E34-C34 | E34: =非流动资产汇总!D21 | F34: =非流动资产汇总!E21 | G34: =F34-E34 | H34: =IF(E34=0,"",G34/ABS(E34)*100) | I34: =资产负债表!D34 | J34: =ROUND(E34-I34,2)
A35: 30 | B35: 递延所得税资产 | C35: =非流动资产汇总!C22 | D35: =E35-C35 | E35: =非流动资产汇总!D22 | F35: =非流动资产汇总!E22 | G35: =F35-E35 | H35: =IF(E35=0,"",G35/ABS(E35)*100) | I35: =资产负债表!D35 | J35: =ROUND(E35-I35,2)
A36: 31 | B36: 其他非流动资产 | C36: =非流动资产汇总!C23 | D36: =E36-C36 | E36: =非流动资产汇总!D23 | F36: =非流动资产汇总!E23 | G36: =F36-E36 | H36: =IF(E36=0,"",G36/ABS(E36)*100) | I36: =资产负债表!D36 | J36: =ROUND(E36-I36,2)
A37: 32 | H37: =IF(E37=0,"",G37/ABS(E37)*100) | J37: =ROUND(E37-I37,2)
A38: 33 | B38: 三、资产总计 | C38: =SUM(C6,C19) | D38: =SUM(D6,D19) | E38: =SUM(E6,E19) | F38: =SUM(F6,F19) | G38: =SUM(G6,G19) | H38: =IF(E38=0,"",G38/ABS(E38)*100) | I38: =资产负债表!D38 | J38: =ROUND(E38-I38,2)
A39: 35 | B39: 四、流动负债合计 | C39: =SUM(C40:C51) | D39: =SUM(D40:D51) | E39: =SUM(E40:E51) | F39: =SUM(F40:F51) | G39: =SUM(G40:G51) | H39: =IF(E39=0,"",G39/ABS(E39)*100) | I39: =资产负债表!I19 | J39: =ROUND(E39-I39,2)
A40: 36 | B40: 短期借款 | C40: =流动负债汇总!C6 | D40: =E40-C40 | E40: =流动负债汇总!D6 | F40: =流动负债汇总!E6 | G40: =F40-E40 | H40: =IF(E40=0,"",G40/ABS(E40)*100) | I40: =资产负债表!I7 | J40: =ROUND(E40-I40,2)
...

Sheet 流动汇总
A1: 返回索引页 | B1: 返回
A2: 流动资产评估汇总表
A3: =CONCATENATE(封面!D9,封面!F9,封面!G9,封面!H9,封面!I9,封面!J9,封面!K9)
A4: =封面!D7&封面!F7 | I4: 金额单位：人民币元
A5: 编号 | B5: 科目名称 | E5: 审计前账面值 | F5: 账面价值 | G5: 评估价值 | H5: 增值额 | I5: 增值率%
A6: 3-1 | B6: 货币资金（现金 | C6: 存款 | D6: 他币） | E6: =SUM(现金!F27,银行存款!G23,其他货币资金!G20) | F6: =SUM(现金!H27,银行存款!I23,其他货币资金!I20) | G6: =SUM(现金!I27,银行存款!J23,其他货币资金!J20) | H6: =G6-F6 | I6: =IF(F6=0,"",H6/F6*100)
A7: 3-2 | B7: 交易性金融资产 | E7: =交易性金融资产汇总!C27 | F7: =交易性金融资产汇总!D27 | G7: =交易性金融资产汇总!E27 | H7: =G7-F7 | I7: =IF(F7=0,"",H7/F7*100)
A8: 3-3 | B8: 应收票据 | E8: =应收票据!F27 | F8: =应收票据!H27 | G8: =应收票据!I27 | H8: =G8-F8 | I8: =IF(F8=0,"",H8/F8*100)
A9: 3-4 | B9: 应收账款 | E9: =应收账款!F27 | F9: =应收账款!P27 | G9: =应收账款!Q27 | H9: =G9-F9 | I9: =IF(F9=0,"",H9/F9*100)
A10: 3-5 | B10: 预付账款 | E10: =预付账款!F27 | F10: =预付账款!H27 | G10: =预付账款!I27 | H10: =G10-F10 | I10: =IF(F10=0,"",H10/F10*100)
A11: 3-6 | B11: 应收利息 | E11: =应收利息!G27 | F11: =应收利息!I27 | G11: =应收利息!J27 | H11: =G11-F11 | I11: =IF(F11=0,"",H11/F11*100)
A12: 3-7 | B12: 应收股利（应收利润） | E12: ='应收股利（利润）'!E27 | F12: ='应收股利（利润）'!G27 | G12: ='应收股利（利润）'!H27 | H12: =G12-F12 | I12: =IF(F12=0,"",H12/F12*100)
A13: 3-8 | B13: 其他应收款 | E13: =其他应收款!F45 | F13: =其他应收款!P45 | G13: =其他应收款!Q45 | H13: =G13-F13 | I13: =IF(F13=0,"",H13/F13*100)
A14: 3-9 | B14: 存货 | E14: =存货汇总!C27 | F14: =存货汇总!D27 | G14: =存货汇总!E27 | H14: =G14-F14 | I14: =IF(F14=0,"",H14/F14*100)
A15: 3-10 | B15: 一年内到期的非流动资产 | E15: =一年到期非流动资产!E27 | F15: =一年到期非流动资产!G27 | G15: =一年到期非流动资产!H27 | H15: =G15-F15 | I15: =IF(F15=0,"",H15/F15*100)
A16: 3-11 | B16: 其他流动资产 | E16: =其他流动资产!E27 | F16: =其他流动资产!G27 | G16: =其他流动资产!H27 | H16: =G16-F16 | I16: =IF(F16=0,"",H16/F16*100)
I17: =IF(F17=0,"",H17/F17*100)
I18: =IF(F18=0,"",H18/F18*100)
I19: =IF(F19=0,"",H19/F19*100)
I20: =IF(F20=0,"",H20/F20*100)
I21: =IF(F21=0,"",H21/F21*100)
I22: =IF(F22=0,"",H22/F22*100)
I23: =IF(F23=0,"",H23/F23*100)
I24: =IF(F24=0,"",H24/F24*100)
I25: =IF(F25=0,"",H25/F25*100)
A27: 3 | B27: 流动资产合计 | E27: =SUM(E6:E26) | F27: =SUM(F6:F26) | G27: =SUM(G6:G26) | H27: =SUM(H6:H26) | I27: =IF(F27=0,"",H27/F27*100)
A28: =封面!D11&封面!G11 | G28: ="评估人员："&封面!G20
A29: =CONCATENATE(封面!D13,封面!F13,封面!G13,封面!H13,封面!I13,封面!J13,封面!K13)

Sheet 现金
A1: 返回索引页 | B1: 返回
A2: 货币资金—现金评估明细表
A3: =CONCATENATE(封面!D9,封面!F9,封面!G9,封面!H9,封面!I9,封面!J9,封面!K9)
A4: =封面!D7&封面!F7 | J4: 金额单位：人民币元
A5: 序号 | B5: 存放部门（单位） | C5: 币种 | D5: 外币账面金额 | E5: 评估基准日汇率 | F5: 审计前账面值 | G5: 审计调整 | H5: 账面价值 | I5: 评估价值 | J5: 增值率%
A6: 1 | I6: =H6 | J6: =IF(H6=0,"",(I6-H6)/H6*100)
J7: =IF(H7=0,"",(I7-H7)/H7*100)
J8: =IF(H8=0,"",(I8-H8)/H8*100)
J9: =IF(H9=0,"",(I9-H9)/H9*100)
J10: =IF(H10=0,"",(I10-H10)/H10*100)
J11: =IF(H11=0,"",(I11-H11)/H11*100)
J12: =IF(H12=0,"",(I12-H12)/H12*100)
J13: =IF(H13=0,"",(I13-H13)/H13*100)
J14: =IF(H14=0,"",(I14-H14)/H14*100)
J15: =IF(H15=0,"",(I15-H15)/H15*100)
J16: =IF(H16=0,"",(I16-H16)/H16*100)
J17: =IF(H17=0,"",(I17-H17)/H17*100)
J18: =IF(H18=0,"",(I18-H18)/H18*100)
... J25: =IF(H25=0,"",(I25-H25)/H25*100)
A27: 合 计 | F27: =SUM(F6:F26) | H27: =SUM(H6:H26) | I27: =SUM(I6:I26) | J27: =IF(H27=0,"",(I27-H27)/H27*100)
A28: =封面!D11&封面!G11 | H28: ="评估人员："&封面!G20
A29: =CONCATENATE(封面!D13,封面!F13,封面!G13,封面!H13,封面!I13,封面!J13,封面!K13)

Sheet 银行存款
A1: 返回索引页 | B1: 返回
A2: 货币资金—银行存款评估明细表
A3: =CONCATENATE(封面!D9,封面!F9,封面!G9,封面!H9,封面!I9,封面!J9,封面!K9)
A4: =封面!D7&封面!F7 | K4: 金额单位：人民币元
A5: 序号 | B5: 开户银行 | C5: 账号 | D5: 币种 | E5: 外币账面金额 | F5: 评估基准日汇率 | G5: 审计前账面值 | H5: 审计调整 | I5: 账面价值 | J5: 评估价值 | K5: 增值率%
A6: 1 | J6: =I6 | K6: =IF(I6=0,"",(J6-I6)/I6*100)
J7: =I7 | K7: =IF(I7=0,"",(J7-I7)/I7*100)
J8: =I8 | K8: =IF(I8=0,"",(J8-I8)/I8*100)
J9: =I9 | K9: =IF(I9=0,"",(J9-I9)/I9*100)
J10: =I10 | K10: =IF(I10=0,"",(J10-I10)/I10*100)
J11: =I11 | K11: =IF(I11=0,"",(J11-I11)/I11*100)
J13: =I13 | K13: =IF(I13=0,"",(J13-I13)/I13*100)
J14: =I14 | K14: =IF(I14=0,"",(J14-I14)/I14*100)
J15: =I15 | K15: =IF(I15=0,"",(J15-I15)/I15*100)
J16: =I16 | K16: =IF(I16=0,"",(J16-I16)/I16*100)
J17: =I17 | K17: =IF(I17=0,"",(J17-I17)/I17*100)
J18: =I18 | K18: =IF(I18=0,"",(J18-I18)/I18*100)
J19: =I19 | K19: =IF(I19=0,"",(J19-I19)/I19*100)
J20: =I20 | K20: =IF(I20=0,"",(J20-I20)/I20*100)
K21: =IF(I21=0,"",(J21-I21)/I21*100)
A23: 合 计 | G23: =SUM(G6:G22) | I23: =SUM(I6:I22) | J23: =SUM(J6:J22) | K23: =IF(I23=0,"",(J23-I23)/I23*100)
A24: =封面!D11&封面!G11 | I24: ="评估人员："&封面!G20
A25: =CONCATENATE(封面!D13,封面!F13,封面!G13,封面!H13,封面!I13,封面!J13,封面!K13)

Sheet 其他货币资金
A1: 返回索引页 | B1: 返回
A2: 货币资金—其他货币资金评估明细表
A3: =CONCATENATE(封面!D9,封面!F9,封面!G9,封面!H9,封面!I9,封面!J9,封面!K9)
A4: =封面!D7&封面!F7 | L4: 金额单位：人民币元
A5: 序号 | B5: 名称及内容 | C5: 用途 | D5: 币种 | E5: 外币账面金额 | F5: 评估基准日汇率 | G5: 审计前账面值 | H5: 审计调整 | I5: 账面价值 | J5: 评估价值 | K5: 增值率% | L5: 备注
A6: 1 | K6: =IF(I6=0,"",(J6-I6)/I6*100)
A7: 2 | K7: =IF(I7=0,"",(J7-I7)/I7*100)
A8: 3 | K8: =IF(I8=0,"",(J8-I8)/I8*100)
A9: 4 | K9: =IF(I9=0,"",(J9-I9)/I9*100)
A10: 5 | K10: =IF(I10=0,"",(J10-I10)/I10*100)
A11: 6 | K11: =IF(I11=0,"",(J11-I11)/I11*100)
K17: =IF(I17=0,"",(J17-I17)/I17*100)
K18: =IF(I18=0,"",(J18-I18)/I18*100)
A20: 合 计 | G20: =SUM(G6:G19) | I20: =SUM(I6:I19) | J20: =SUM(J6:J19) | K20: =IF(I20=0,"",(J20-I20)/I20*100)
A21: =封面!D11&封面!G11 | I21: ="评估人员："&封面!G20
A22: =CONCATENATE(封面!D13,封面!F13,封面!G13,封面!H13,封面!I13,封面!J13,封面!K13)

Sheet 交易性金融资产汇总
A1: 返回索引页 | B1: 返回
A2: 交易性金融资产评估汇总表
A3: =CONCATENATE(封面!D9,封面!F9,封面!G9,封面!H9,封面!I9,封面!J9,封面!K9)
A4: =封面!D7&封面!F7 | G4: 金额单位：人民币元
A5: 编号 | B5: 科目名称 | C5: 审计前账面值 | D5: 账面价值 | E5: 评估价值 | F5: 增值额 | G5: 增值率%
A6: 3-2-1 | B6: 交易性金融资产-股票投资 | C6: ='交易性-股票'!G27 | D6: ='交易性-股票'!I27 | E6: ='交易性-股票'!K27 | F6: =E6-D6 | G6: =IF(D6=0,"",F6/D6*100)
A7: 3-2-2 | B7: 交易性金融资产-债券投资 | C7: ='交易性-债券'!H27 | D7: ='交易性-债券'!J27 | E7: ='交易性-债券'!K27 | F7: =E7-D7 | G7: =IF(D7=0,"",F7/D7*100)
A8: 3-2-3 | B8: 交易性金融资产-基金投资 | C8: ='交易性-基金'!H27 | D8: ='交易性-基金'!J27 | E8: ='交易性-基金'!L27 | F8: =E8-D8 | G8: =IF(D8=0,"",F8/D8*100)
A27: 3-2 | B27: 交易性金融资产合计 | C27: =SUM(C6:C26) | D27: =SUM(D6:D26) | E27: =SUM(E6:E26) | F27: =SUM(F6:F26) | G27: =IF(D27=0,"",F27/D27*100)
A28: =封面!D11&封面!G11 | E28: ="评估人员："&封面!G20
A29: =CONCATENATE(封面!D13,封面!F13,封面!G13,封面!H13,封面!I13,封面!J13,封面!K13)

Sheet 交易性-股票
A1: 返回索引页 | B1: 返回
A2: 交易性金融资产—股票投资评估明细表
A3: =CONCATENATE(封面!D9,封面!F9,封面!G9,封面!H9,封面!I9,封面!J9,封面!K9)
A4: =封面!D7&封面!F7 | L4: 金额单位：人民币元
A5: 序号 | B5: 被投资单位名称 | C5: 股票名称 | D5: 投资日期 | E5: 持股数量 | F5: 成本 | G5: 审计前账面值 | H5: 审计调整 | I5: 账面价值 | J5: 基准日收盘价/股 | K5: 评估价值 | L5: 增值率%
L6: =IF(I6=0,"",(K6-I6)/I6*100)
L7: =IF(I7=0,"",(K7-I7)/I7*100)
L8: =IF(I8=0,"",(K8-I8)/I8*100)
L9: =IF(I9=0,"",(K9-I9)/I9*100)
L10: =IF(I10=0,"",(K10-I10)/I10*100)
L11: =IF(I11=0,"",(K11-I11)/I11*100)
L12: =IF(I12=0,"",(K12-I12)/I12*100)
L13: =IF(I13=0,"",(K13-I13)/I13*100)
L14: =IF(I14=0,"",(K14-I14)/I14*100)
L15: =IF(I15=0,"",(K15-I15)/I15*100)
L16: =IF(I16=0,"",(K16-I16)/I16*100)
L17: =IF(I17=0,"",(K17-I17)/I17*100)
... L25: =IF(I25=0,"",(K25-I25)/I25*100)
A27: 合 计 | G27: =SUM(G6:G26) | I27: =SUM(I6:I26) | K27: =SUM(K6:K26) | L27: =IF(I27=0,"",(K27-I27)/I27*100)
A28: =封面!D11&封面!G11 | I28: ="评估人员："&封面!G20
A29: =CONCATENATE(封面!D13,封面!F13,封面!G13,封面!H13,封面!I13,封面!J13,封面!K13)

Sheet 交易性-债券
A1: 返回索引页 | B1: 返回
A2: 交易性金融资产—债券投资评估明细表
A3: =CONCATENATE(封面!D9,封面!F9,封面!G9,封面!H9,封面!I9,封面!J9,封面!K9)
A4: =封面!D7&封面!F7 | L4: 金额单位：人民币元
A5: 序号 | B5: 被投资单位名称 | C5: 债券名称 | D5: 发行日期 | E5: 投资日期 | F5: 票面利率% | G5: 成本 | H5: 审计前账面值 | I5: 审计调整 | J5: 账面价值 | K5: 评估价值 | L5: 增值率%
L6: =IF(J6=0,"",(K6-J6)/J6*100)
L7: =IF(J7=0,"",(K7-J7)/J7*100)
L8: =IF(J8=0,"",(K8-J8)/J8*100)
L9: =IF(J9=0,"",(K9-J9)/J9*100)
L10: =IF(J10=0,"",(K10-J10)/J10*100)
L11: =IF(J11=0,"",(K11-J11)/J11*100)
L12: =IF(J12=0,"",(K12-J12)/J12*100)
L13: =IF(J13=0,"",(K13-J13)/J13*100)
L14: =IF(J14=0,"",(K14-J14)/J14*100)
L15: =IF(J15=0,"",(K15-J15)/J15*100)
L16: =IF(J16=0,"",(K16-J16)/J16*100)
L17: =IF(J17=0,"",(K17-J17)/J17*100)
... L25: =IF(J25=0,"",(K25-J25)/J25*100)
A27: 合 计 | H27: =SUM(H6:H26) | J27: =SUM(J6:J26) | K27: =SUM(K6:K26) | L27: =IF(J27=0,"",(K27-J27)/J27*100)
A28: =封面!D11&封面!G11 | J28: ="评估人员："&封面!G20
A29: =CONCATENATE(封面!D13,封面!F13,封面!G13,封面!H13,封面!I13,封面!J13,封面!K13)

Sheet 交易性-基金
A1: 返回索引页 | B1: 返回
A2: 交易性金融资产—基金投资评估明细表
A3: =CONCATENATE(封面!D9,封面!F9,封面!G9,封面!H9,封面!I9,封面!J9,封面!K9)
A4: =封面!D7&封面!F7 | M4: 金额单位：人民币元
A5: 序号 | B5: 基金发行单位 | C5: 基金名称 | D5: 基金类型 | E5: 投资日期 | F5: 基金份额 | G5: 成本 | H5: 审计前账面值 | I5: 审计调整 | J5: 账面价值 | K5: 基准日净值/份 | L5: 评估价值 | M5: 增值率%
M6: =IF(J6=0,"",(L6-J6)/J6*100)
M7: =IF(J7=0,"",(L7-J7)/J7*100)
M8: =IF(J8=0,"",(L8-J8)/J8*100)
M9: =IF(J9=0,"",(L9-J9)/J9*100)
M10: =IF(J10=0,"",(L10-J10)/J10*100)
M11: =IF(J11=0,"",(L11-J11)/J11*100)
M12: =IF(J12=0,"",(L12-J12)/J12*100)
M13: =IF(J13=0,"",(L13-J13)/J13*100)
M14: =IF(J14=0,"",(L14-J14)/J14*100)
M15: =IF(J15=0,"",(L15-J15)/J15*100)
M16: =IF(J16=0,"",(L16-J16)/J16*100)
M17: =IF(J17=0,"",(L17-J17)/J17*100)
... M25: =IF(J25=0,"",(L25-J25)/J25*100)
A27: 合 计 | H27: =SUM(H6:H26) | J27: =SUM(J6:J26) | L27: =SUM(L6:L26) | M27: =IF(J27=0,"",(L27-J27)/J27*100)
A28: =封面!D11&封面!G11 | J28: ="评估人员："&封面!G20
A29: =CONCATENATE(封面!D13,封面!F13,封面!G13,封面!H13,封面!I13,封面!J13,封面!K13)

Sheet 应收票据
A1: 返回索引页 | B1: 返回
A2: 应收票据评估明细表
A3: =CONCATENATE(封面!D9,封面!F9,封面!G9,封面!H9,封面!I9,封面!J9,封面!K9)
A4: =封面!D7&封面!F7 | K4: 金额单位：人民币元
A5: 序号 | B5: 户名（结算对象） | C5: 出票日期 | D5: 到期日期 | E5: 票面利率% | F5: 审计前账面值 | G5: 审计调整 | H5: 账面价值 | I5: 评估价值 | J5: 增值率% | K5: 备注
J6: =IF(H6=0,"",(I6-H6)/H6*100)
J7: =IF(H7=0,"",(I7-H7)/H7*100)
J8: =IF(H8=0,"",(I8-H8)/H8*100)
J9: =IF(H9=0,"",(I9-H9)/H9*100)
J10: =IF(H10=0,"",(I10-H10)/H10*100)
J11: =IF(H11=0,"",(I11-H11)/H11*100)
J12: =IF(H12=0,"",(I12-H12)/H12*100)
J13: =IF(H13=0,"",(I13-H13)/H13*100)
J14: =IF(H14=0,"",(I14-H14)/H14*100)
J15: =IF(H15=0,"",(I15-H15)/H15*100)
J16: =IF(H16=0,"",(I16-H16)/H16*100)
J17: =IF(H17=0,"",(I17-H17)/H17*100)
... J26: =IF(H26=0,"",(I26-H26)/H26*100)
A27: 合 计 | F27: =SUM(F6:F26) | H27: =SUM(H6:H26) | I27: =SUM(I6:I26) | J27: =IF(H27=0,"",(I27-H27)/H27*100)
A28: =封面!D11&封面!G11 | H28: ="评估人员："&封面!G20
A29: =CONCATENATE(封面!D13,封面!F13,封面!G13,封面!H13,封面!I13,封面!J13,封面!K13)

Sheet 应收账款
A1: 返回索引页 | B1: 返回
A2: 应收账款评估明细表
A3: =CONCATENATE(封面!D9,封面!F9,封面!G9,封面!H9,封面!I9,封面!J9,封面!K9)
A4: =封面!D7&封面!F7 | M4: 账龄总数与审计前账面值差异(应等于0) | N4: 预计不可收回金额(注1) | S4: 金额单位：人民币元
A5: 序号 | B5: 欠款单位名称（结算对象） | C5: 业务内容 | D5: 发生日期 | E5: 账龄 | F5: 审计前账面值 | G5: 1年以内金额 | H5: 1~2年金额 | I5: 2~3年金额 | J5: 3~4年金额 | K5: 4~5年金额 | L5: 5年以上金额 | O5: 审计调整 | P5: 账面价值 | Q5: 评估价值 | R5: 增值率% | S5: 备注
A6: 1 | Q6: =P6 | R6: =IF(P6=0,"",(Q6-P6)/P6*100)
A24: 合 计 | F24: =SUM(F6:F23) | G24: =SUM(G6:G23) | H24: =SUM(H6:H23) | I24: =SUM(I6:I23) | J24: =SUM(J6:J23) | K24: =SUM(K6:K23) | L24: =SUM(L6:L23) | M24: =SUM(M6:M23) | N24: =SUM(N6:N23) | P24: =SUM(P6:P23) | Q24: =SUM(Q6:Q23) | R24: =IF(P24=0,"",(Q24-P24)/P24*100)
A25: 减：坏账准备 | M25: =SUM(G25:L25)-F25 | P25: =F24 | R25: =IF(P25=0,"",(Q25-P25)/P25*100)
A26: 减：评估风险损失 | R26: =IF(P26=0,"",(Q26-P26)/P26*100)
A27: 净 额 | F27: =F24-F25-F26 | G27: =G24-G25-G26 | H27: =H24-H25-H26 | I27: =I24-I25-I26 | J27: =J24-J25-J26 | K27: =K24-K25-K26 | L27: =L24-L25-L26 | M27: =M24-M25-M26 | N27: =N24-N25-N26 | P27: =P24-P25-P26 | Q27: =Q24-Q25-Q26 | R27: =IF(P27=0,"",(Q27-P27)/P27*100)
A28: =封面!D11&封面!G11 | P28: ="评估人员："&封面!G20
A29: =CONCATENATE(封面!D13,封面!F13,封面!G13,封面!H13,封面!I13,封面!J13,封面!K13)
B30: 注1： | C30: 注明账齡在一年以上的账款的可收回性，若有部分可能不能收回，请估计不能收回的金額，以供评估时作參考。
B31: 注2：“备注”栏填写方法： | C31: 1）欠款单位为关联方、总公司内部或本公司内部单位的，应在备注栏注明“关联方”、“总公司内部”、“内部单位”；
C32: 2） 涉诉款项应在备注中标明“涉诉”；
C33: 3）评估基准日后已部分或全部收回款项的，应注明日期及金额，如“2003年2月4日收回8,530.00元”；
C34: 4）填表单位认为其他应说明的事项

Sheet 预付账款
A1: 返回索引页 | B1: 返回
A2: 预付账款评估明细表
A3: =CONCATENATE(封面!D9,封面!F9,封面!G9,封面!H9,封面!I9,封面!J9,封面!K9)
A4: =封面!D7&封面!F7 | K4: 金额单位：人民币元
A5: 序号 | B5: 收款单位名称（结算对象） | C5: 业务内容 | D5: 发生日期 | E5: 账龄 | F5: 审计前账面值 | G5: 审计调整 | H5: 账面价值 | I5: 评估价值 | J5: 增值率% | K5: 备注
A6: 1 | I6: =H6 | J6: =IF(H6=0,"",(I6-H6)/H6*100)
A7: 2 | I7: =H7 | J7: =IF(H7=0,"",(I7-H7)/H7*100)
A27: 合 计 | F27: =SUM(F6:F26) | H27: =SUM(H6:H26) | I27: =SUM(I6:I26) | J27: =IF(H27=0,"",(I27-H27)/H27*100)
A28: =封面!D11&封面!G11 | H28: ="评估人员："&封面!G20
A29: =CONCATENATE(封面!D13,封面!F13,封面!G13,封面!H13,封面!I13,封面!J13,封面!K13)

Sheet 应收利息
A1: 返回索引页 | B1: 返回
A2: 应收利息评估明细表
A3: =CONCATENATE(封面!D9,封面!F9,封面!G9,封面!H9,封面!I9,封面!J9,封面!K9)
A4: =封面!D7&封面!F7 | L4: 金额单位：人民币元
A5: 序号 | B5: 欠款单位名称（结算对象） | C5: 发生日期 | D5: 本金 | E5: 利息所属期间 | F5: 利息率% | G5: 审计前账面值 | H5: 审计调整 | I5: 账面价值 | J5: 评估价值 | K5: 增值率% | L5: 备注
K6: =IF(I6=0,"",(J6-I6)/I6*100)
K7: =IF(I7=0,"",(J7-I7)/I7*100)
K8: =IF(I8=0,"",(J8-I8)/I8*100)
K9: =IF(I9=0,"",(J9-I9)/I9*100)
K10: =IF(I10=0,"",(J10-I10)/I10*100)
K11: =IF(I11=0,"",(J11-I11)/I11*100)
K12: =IF(I12=0,"",(J12-I12)/I12*100)
K13: =IF(I13=0,"",(J13-I13)/I13*100)
K14: =IF(I14=0,"",(J14-I14)/I14*100)
K15: =IF(I15=0,"",(J15-I15)/I15*100)
K16: =IF(I16=0,"",(J16-I16)/I16*100)
K17: =IF(I17=0,"",(J17-I17)/I17*100)
... K25: =IF(I25=0,"",(J25-I25)/I25*100)
A27: 合 计 | D27: =SUM(D6:D26) | G27: =SUM(G6:G26) | I27: =SUM(I6:I26) | J27: =SUM(J6:J26) | K27: =IF(I27=0,"",(J27-I27)/I27*100)
A28: =封面!D11&封面!G11 | I28: ="评估人员："&封面!G20
A29: =CONCATENATE(封面!D13,封面!F13,封面!G13,封面!H13,封面!I13,封面!J13,封面!K13)

Sheet 应收股利（利润）
A1: 返回索引页 | B1: 返回
A2: 应收股利（应收利润）评估明细表
A3: =CONCATENATE(封面!D9,封面!F9,封面!G9,封面!H9,封面!I9,封面!J9,封面!K9)
A4: =封面!D7&封面!F7 | J4: 金额单位：人民币元
A5: 序号 | B5: 户名（结算对象） | C5: 发生日期 | D5: 股利所属期间 | E5: 审计前账面值 | F5: 审计调整 | G5: 账面价值 | H5: 评估价值 | I5: 增值率% | J5: 备注
I6: =IF(G6=0,"",(H6-G6)/G6*100)
I7: =IF(G7=0,"",(H7-G7)/G7*100)
I8: =IF(G8=0,"",(H8-G8)/G8*100)
I9: =IF(G9=0,"",(H9-G9)/G9*100)
I10: =IF(G10=0,"",(H10-G10)/G10*100)
I11: =IF(G11=0,"",(H11-G11)/G11*100)
I12: =IF(G12=0,"",(H12-G12)/G12*100)
I13: =IF(G13=0,"",(H13-G13)/G13*100)
I14: =IF(G14=0,"",(H14-G14)/G14*100)
I15: =IF(G15=0,"",(H15-G15)/G15*100)
I16: =IF(G16=0,"",(H16-G16)/G16*100)
I17: =IF(G17=0,"",(H17-G17)/G17*100)
... I25: =IF(G25=0,"",(H25-G25)/G25*100)
A27: 合 计 | E27: =SUM(E6:E26) | G27: =SUM(G6:G26) | H27: =SUM(H6:H26) | I27: =IF(G27=0,"",(H27-G27)/G27*100)
A28: =封面!D11&封面!G11 | G28: ="评估人员："&封面!G20
A29: =CONCATENATE(封面!D13,封面!F13,封面!G13,封面!H13,封面!I13,封面!J13,封面!K13)

Sheet 其他应收款
A1: 返回索引页 | B1: 返回
A2: 其他应收款评估明细表
A3: =CONCATENATE(封面!D9,封面!F9,封面!G9,封面!H9,封面!I9,封面!J9,封面!K9)
A4: =封面!D7&封面!F7 | M4: 账龄总数与审计前账面值差异(应等于0) | N4: 预计不可收回金额(注1) | S4: 金额单位：人民币元
A5: 序号 | B5: 欠款单位名称（结算对象） | C5: 业务内容 | D5: 发生日期 | E5: 账龄 | F5: 审计前账面值 | G5: 1年以内金额 | H5: 1~2年金额 | I5: 2~3年金额 | J5: 3~4年金额 | K5: 4~5年金额 | L5: 5年以上金额 | O5: 审计调整 | P5: 账面价值 | Q5: 评估价值 | R5: 增值率% | S5: 备注
A6: 1 | Q6: =P6 | R6: =IF(P6=0,"",(Q6-P6)/P6*100)
A7: 2 | Q7: =P7 | R7: =IF(P7=0,"",(Q7-P7)/P7*100)
A8: 3 | Q8: =P8 | R8: =IF(P8=0,"",(Q8-P8)/P8*100)
A9: 4 | Q9: =P9 | R9: =IF(P9=0,"",(Q9-P9)/P9*100)
A10: 5 | Q10: =P10 | R10: =IF(P10=0,"",(Q10-P10)/P10*100)
A11: 6 | Q11: =P11 | R11: =IF(P11=0,"",(Q11-P11)/P11*100)
A12: 7 | Q12: =P12 | R12: =IF(P12=0,"",(Q12-P12)/P12*100)
A13: 8 | Q13: =P13 | R13: =IF(P13=0,"",(Q13-P13)/P13*100)
A14: 9 | Q14: =P14 | R14: =IF(P14=0,"",(Q14-P14)/P14*100)
A15: 10 | Q15: =P15 | R15: =IF(P15=0,"",(Q15-P15)/P15*100)
A16: 11 | Q16: =P16 | R16: =IF(P16=0,"",(Q16-P16)/P16*100)
A17: 12 | Q17: =P17 | R17: =IF(P17=0,"",(Q17-P17)/P17*100)
... A41: 36 | Q41: =P41 | R41: =IF(P41=0,"",(Q41-P41)/P41*100)
A42: 合 计 | F42: =SUM(F6:F41) | G42: =SUM(G6:G41) | H42: =SUM(H6:H41) | I42: =SUM(I6:I41) | J42: =SUM(J6:J41) | K42: =SUM(K6:K41) | L42: =SUM(L6:L41) | M42: =SUM(M6:M41) | N42: =SUM(N6:N41) | P42: =SUM(P6:P41) | Q42: =SUM(Q6:Q41) | R42: =IF(P30=0,"",(Q30-P30)/P30*100)
A43: 减：坏账准备 | M43: =SUM(G31:L31)-F31 | P43: =F31 | R43: =IF(P31=0,"",(Q31-P31)/P31*100)
A44: 减：评估风险损失 | R44: =IF(P32=0,"",(Q32-P32)/P32*100)
A45: 净 额 | F45: =F30-F31-F32 | G45: =G30-G31-G32 | H45: =H30-H31-H32 | I45: =I30-I31-I32 | J45: =J30-J31-J32 | K45: =K30-K31-K32 | L45: =L30-L31-L32 | M45: =M30-M31-M32 | N45: =N30-N31-N32 | P45: =P42-P43 | Q45: =Q42-Q44 | R45: =IF(P33=0,"",(Q33-P33)/P33*100)
A46: =封面!D11&封面!G11 | P46: ="评估人员："&封面!G20
A47: =CONCATENATE(封面!D13,封面!F13,封面!G13,封面!H13,封面!I13,封面!J13,封面!K13)
B48: 注1： | C48: 注明账齡在一年以上的账款的可收回性，若有部分可能不能收回，请估计不能收回的金額，以供评估时作參考。
B49: 注2：“备注”栏填写方法： | C49: 1）欠款单位为关联方、总公司内部或本公司内部单位的，应在备注栏注明“关联方”、“总公司内部”、“内部单位”；
C50: 2） 涉诉款项应在备注中标明“涉诉”；
C51: 3）评估基准日后已部分或全部收回款项的，应注明日期及金额，如“2003年2月4日收回8,530.00元”；
C52: 4）填表单位认为其他应说明的事项

Sheet 存货汇总
A1: 返回索引页 | B1: 返回
A2: 存货评估汇总表
A3: =CONCATENATE(封面!D9,封面!F9,封面!G9,封面!H9,封面!I9,封面!J9,封面!K9)
A4: =封面!D7&封面!F7 | G4: 金额单位：人民币元
A5: 编号 | B5: 科目名称 | C5: 审计前账面值 | D5: 账面价值 | E5: 评估价值 | F5: 增值额 | G5: 增值率%
A6: 3-9-1 | B6: 材料采购（在途物资） | C6: ='材料采购（在途物资）'!F27 | D6: ='材料采购（在途物资）'!J27 | E6: ='材料采购（在途物资）'!M27 | F6: =E6-D6 | G6: =IF(D6=0,"",F6/D6*100)
A7: 3-9-2 | B7: 原材料 | C7: =原材料!F277 | D7: =原材料!J277 | E7: =原材料!M277 | F7: =E7-D7 | G7: =IF(D7=0,"",F7/D7*100)
A8: 3-9-3 | B8: 在库周转材料 | C8: =在库周转材料!F27 | D8: =在库周转材料!J27 | E8: =在库周转材料!M27 | F8: =E8-D8 | G8: =IF(D8=0,"",F8/D8*100)
A9: 3-9-4 | B9: 委托加工物资 | C9: =委托加工物资!G27 | D9: =委托加工物资!K27 | E9: =委托加工物资!N27 | F9: =E9-D9 | G9: =IF(D9=0,"",F9/D9*100)
A10: 3-9-5 | B10: 产成品（库存商品） | C10: ='产成品（库存商品）'!F27 | D10: ='产成品（库存商品）'!J27 | E10: ='产成品（库存商品）'!M27 | F10: =E10-D10 | G10: =IF(D10=0,"",F10/D10*100)
A11: 3-9-6 | B11: 在产品（自制半成品） | C11: ='在产品（自制半成品）'!F27 | D11: ='在产品（自制半成品）'!J27 | E11: ='在产品（自制半成品）'!M27 | F11: =E11-D11 | G11: =IF(D11=0,"",F11/D11*100)
A12: 3-9-7 | B12: 发出商品 | C12: =发出商品!G37 | D12: =发出商品!K37 | E12: =发出商品!N37 | F12: =E12-D12 | G12: =IF(D12=0,"",F12/D12*100)
A13: 3-9-8 | B13: 在用周转材料 | C13: =在用周转材料!G27 | D13: =在用周转材料!J27 | E13: =在用周转材料!N27 | F13: =E13-D13 | G13: =IF(D13=0,"",F13/D13*100)
A25: 3-10 | B25: 存货合计 | C25: =SUM(C6:C24) | D25: =SUM(D6:D24) | E25: =SUM(E6:E24) | F25: =SUM(F6:F24) | G25: =IF(D25=0,"",F25/D25*100)
A26: 3-10 | B26: 减：存货跌价准备 | D26: =C26 | E26: 0 | F26: =E26-D26 | G26: =IF(D26=0,"",F26/D26*100)
A27: 3-10 | B27: 存货净额 | C27: =C25-C26 | D27: =D25-D26 | E27: =E25-E26 | F27: =F25-F26 | G27: =IF(D27=0,"",F27/D27*100)
A28: =封面!D11&封面!G11 | E28: ="评估人员："&封面!G20
A29: =CONCATENATE(封面!D13,封面!F13,封面!G13,封面!H13,封面!I13,封面!J13,封面!K13)

Sheet 材料采购（在途物资）
A1: 返回索引页 | B1: 返回
A2: 存货—材料采购（在途物资）评估明细表
A3: =CONCATENATE(封面!D9,封面!F9,封面!G9,封面!H9,封面!I9,封面!J9,封面!K9)
A4: =封面!D7&封面!F7 | O4: 金额单位：人民币元
A5: 序号 | B5: 名称及规格型号 | C5: 计量单位 | D5: 审计前账面值 | G5: 审计调整 | H5: 账面价值 | K5: 评估价值 | N5: 增值率% | O5: 备注
D6: 数量 | E6: 单价 | F6: 金额 | H6: 数量 | I6: 单价 | J6: 金额 | K6: 实际数量 | L6: 单价 | M6: 金额
E7: =IF(D7=0,"",F7/D7) | N7: =IF(J7=0,"",(M7-J7)/J7*100)
E8: =IF(D8=0,"",F8/D8) | N8: =IF(J8=0,"",(M8-J8)/J8*100)
E9: =IF(D9=0,"",F9/D9) | N9: =IF(J9=0,"",(M9-J9)/J9*100)
E10: =IF(D10=0,"",F10/D10) | N10: =IF(J10=0,"",(M10-J10)/J10*100)
E11: =IF(D11=0,"",F11/D11) | N11: =IF(J11=0,"",(M11-J11)/J11*100)
E12: =IF(D12=0,"",F12/D12) | N12: =IF(J12=0,"",(M12-J12)/J12*100)
E13: =IF(D13=0,"",F13/D13) | N13: =IF(J13=0,"",(M13-J13)/J13*100)
E14: =IF(D14=0,"",F14/D14) | N14: =IF(J14=0,"",(M14-J14)/J14*100)
E15: =IF(D15=0,"",F15/D15) | N15: =IF(J15=0,"",(M15-J15)/J15*100)
E16: =IF(D16=0,"",F16/D16) | N16: =IF(J16=0,"",(M16-J16)/J16*100)
E17: =IF(D17=0,"",F17/D17) | N17: =IF(J17=0,"",(M17-J17)/J17*100)
E18: =IF(D18=0,"",F18/D18) | N18: =IF(J18=0,"",(M18-J18)/J18*100)
... E25: =IF(D25=0,"",F25/D25) | N25: =IF(J25=0,"",(M25-J25)/J25*100)
A27: 合 计 | F27: =SUM(F7:F26) | J27: =SUM(J7:J26) | M27: =SUM(M7:M26) | N27: =IF(J27=0,"",(M27-J27)/J27*100)
A28: =封面!D11&封面!G11 | J28: ="评估人员："&封面!G20
A29: =CONCATENATE(封面!D13,封面!F13,封面!G13,封面!H13,封面!I13,封面!J13,封面!K13)

Sheet 原材料
A1: 返回索引页 | B1: 返回
A2: 存货—原材料评估明细表
A3: =CONCATENATE(封面!D9,封面!F9,封面!G9,封面!H9,封面!I9,封面!J9,封面!K9)
A4: =封面!D7&封面!F7 | O4: 金额单位：人民币元
A5: 序号 | B5: 名称及规格型号 | C5: 计量单位 | D5: 审计前账面值 | G5: 审计调整 | H5: 账面价值 | K5: 评估价值 | N5: 增值率% | O5: 备注
D6: 数量 | E6: 单价 | F6: 金额 | H6: 数量 | I6: 单价 | J6: 金额 | K6: 实际数量 | L6: 单价 | M6: 金额
N7: =IF(J7=0,"",(M7-J7)/J7*100)
N8: =IF(J8=0,"",(M8-J8)/J8*100)
N9: =IF(J9=0,"",(M9-J9)/J9*100)
N10: =IF(J10=0,"",(M10-J10)/J10*100)
N11: =IF(J11=0,"",(M11-J11)/J11*100)
N12: =IF(J12=0,"",(M12-J12)/J12*100)
N13: =IF(J13=0,"",(M13-J13)/J13*100)
N14: =IF(J14=0,"",(M14-J14)/J14*100)
N15: =IF(J15=0,"",(M15-J15)/J15*100)
N16: =IF(J16=0,"",(M16-J16)/J16*100)
N17: =IF(J17=0,"",(M17-J17)/J17*100)
N18: =IF(J18=0,"",(M18-J18)/J18*100)
... N263: =IF(J263=0,"",(M263-J263)/J263*100)
E264: =IF(D264=0,"",F264/D264) | N264: =IF(J264=0,"",(M264-J264)/J264*100)
E265: =IF(D265=0,"",F265/D265) | N265: =IF(J265=0,"",(M265-J265)/J265*100)
E266: =IF(D266=0,"",F266/D266) | N266: =IF(J266=0,"",(M266-J266)/J266*100)
E267: =IF(D267=0,"",F267/D267) | N267: =IF(J267=0,"",(M267-J267)/J267*100)
E268: =IF(D268=0,"",F268/D268) | N268: =IF(J268=0,"",(M268-J268)/J268*100)
E269: =IF(D269=0,"",F269/D269) | N269: =IF(J269=0,"",(M269-J269)/J269*100)
E270: =IF(D270=0,"",F270/D270) | N270: =IF(J270=0,"",(M270-J270)/J270*100)
E271: =IF(D271=0,"",F271/D271) | N271: =IF(J271=0,"",(M271-J271)/J271*100)
E272: =IF(D272=0,"",F272/D272) | N272: =IF(J272=0,"",(M272-J272)/J272*100)
E273: =IF(D273=0,"",F273/D273) | N273: =IF(J273=0,"",(M273-J273)/J273*100)
E274: =IF(D274=0,"",F274/D274) | N274: =IF(J274=0,"",(M274-J274)/J274*100)
E275: =IF(D275=0,"",F275/D275) | N275: =IF(J275=0,"",(M275-J275)/J275*100)
A277: 合 计 | F277: =SUM(F7:F276) | J277: =SUM(J7:J276) | M277: =SUM(M7:M276) | N277: =IF(J277=0,"",(M277-J277)/J277*100)
A278: =封面!D11&封面!G11 | J278: ="评估人员："&封面!G20
A279: =CONCATENATE(封面!D13,封面!F13,封面!G13,封面!H13,封面!I13,封面!J13,封面!K13)
B280: 注1： | C280: 1）正常，无需填写；2）残次，填“A”；3）变质，填“B”；4）毁损，填“C”；5）滞销，填“E”；
C281: 6）积压，填“D”并在备注中填写已积压时间“1年以内”、“1~2年”、“2~3年”、“3年以上”；7）其他情形用文字表述。

Sheet 在库周转材料
A1: 返回索引页 | B1: 返回
A2: 存货—在库周转材料评估明细表
A3: =CONCATENATE(封面!D9,封面!F9,封面!G9,封面!H9,封面!I9,封面!J9,封面!K9)
A4: =封面!D7&封面!F7 | O4: 金额单位：人民币元
A5: 序号 | B5: 名称及规格型号 | C5: 计量单位 | D5: 审计前账面值 | G5: 审计调整 | H5: 账面价值 | K5: 评估价值 | N5: 增值率% | O5: 备注 | P5: 存放地点
D6: 数量 | E6: 单价 | F6: 金额 | H6: 数量 | I6: 单价 | J6: 金额 | K6: 实际数量 | L6: 单价 | M6: 金额
E7: =IF(D7=0,"",F7/D7) | N7: =IF(J7=0,"",(M7-J7)/J7*100)
E8: =IF(D8=0,"",F8/D8) | N8: =IF(J8=0,"",(M8-J8)/J8*100)
E9: =IF(D9=0,"",F9/D9) | N9: =IF(J9=0,"",(M9-J9)/J9*100)
E10: =IF(D10=0,"",F10/D10) | N10: =IF(J10=0,"",(M10-J10)/J10*100)
E11: =IF(D11=0,"",F11/D11) | N11: =IF(J11=0,"",(M11-J11)/J11*100)
E12: =IF(D12=0,"",F12/D12) | N12: =IF(J12=0,"",(M12-J12)/J12*100)
E13: =IF(D13=0,"",F13/D13) | N13: =IF(J13=0,"",(M13-J13)/J13*100)
E14: =IF(D14=0,"",F14/D14) | N14: =IF(J14=0,"",(M14-J14)/J14*100)
E15: =IF(D15=0,"",F15/D15) | N15: =IF(J15=0,"",(M15-J15)/J15*100)
E16: =IF(D16=0,"",F16/D16) | N16: =IF(J16=0,"",(M16-J16)/J16*100)
E17: =IF(D17=0,"",F17/D17) | N17: =IF(J17=0,"",(M17-J17)/J17*100)
E18: =IF(D18=0,"",F18/D18) | N18: =IF(J18=0,"",(M18-J18)/J18*100)
... E25: =IF(D25=0,"",F25/D25) | N25: =IF(J25=0,"",(M25-J25)/J25*100)
A27: 合 计 | F27: =SUM(F7:F26) | J27: =SUM(J7:J26) | M27: =SUM(M7:M26) | N27: =IF(J27=0,"",(M27-J27)/J27*100)
A28: =封面!D11&封面!G11 | J28: ="评估人员："&封面!G20
A29: =CONCATENATE(封面!D13,封面!F13,封面!G13,封面!H13,封面!I13,封面!J13,封面!K13)
B30: 注1： | C30: 1）正常，无需填写；2）残次，填“A”；3）变质，填“B”；4）毁损，填“C”；5）滞销，填“E”；
C31: 6）积压，填“D”并在备注中填写已积压时间“1年以内”、“1~2年”、“2~3年”、“3年以上”；7）其他情形用文字表述。

Sheet 委托加工物资
A1: 返回索引页 | B1: 返回
A2: 存货—委托加工物资评估明细表
A3: =CONCATENATE(封面!D9,封面!F9,封面!G9,封面!H9,封面!I9,封面!J9,封面!K9)
A4: =封面!D7&封面!F7 | P4: 金额单位：人民币元
A5: 序号 | B5: 名称及规格型号 | C5: 加工单位名称 | D5: 计量单位 | E5: 审计前账面值 | H5: 审计调整 | I5: 账面价值 | L5: 评估价值 | O5: 增值率% | P5: 备注
E6: 数量 | F6: 单价 | G6: 金额 | I6: 数量 | J6: 单价 | K6: 金额 | L6: 实际数量 | M6: 单价 | N6: 金额
O7: =IF(K7=0,"",(N7-K7)/K7*100)
O8: =IF(K8=0,"",(N8-K8)/K8*100)
O9: =IF(K9=0,"",(N9-K9)/K9*100)
O10: =IF(K10=0,"",(N10-K10)/K10*100)
O11: =IF(K11=0,"",(N11-K11)/K11*100)
F12: =IF(E12=0,"",G12/E12) | O12: =IF(K12=0,"",(N12-K12)/K12*100)
F13: =IF(E13=0,"",G13/E13) | O13: =IF(K13=0,"",(N13-K13)/K13*100)
F14: =IF(E14=0,"",G14/E14) | O14: =IF(K14=0,"",(N14-K14)/K14*100)
F15: =IF(E15=0,"",G15/E15) | O15: =IF(K15=0,"",(N15-K15)/K15*100)
F16: =IF(E16=0,"",G16/E16) | O16: =IF(K16=0,"",(N16-K16)/K16*100)
F17: =IF(E17=0,"",G17/E17) | O17: =IF(K17=0,"",(N17-K17)/K17*100)
F18: =IF(E18=0,"",G18/E18) | O18: =IF(K18=0,"",(N18-K18)/K18*100)
F19: =IF(E19=0,"",G19/E19) | O19: =IF(K19=0,"",(N19-K19)/K19*100)
F20: =IF(E20=0,"",G20/E20) | O20: =IF(K20=0,"",(N20-K20)/K20*100)
F21: =IF(E21=0,"",G21/E21) | O21: =IF(K21=0,"",(N21-K21)/K21*100)
F22: =IF(E22=0,"",G22/E22) | O22: =IF(K22=0,"",(N22-K22)/K22*100)
F23: =IF(E23=0,"",G23/E23) | O23: =IF(K23=0,"",(N23-K23)/K23*100)
... F25: =IF(E25=0,"",G25/E25) | O25: =IF(K25=0,"",(N25-K25)/K25*100)
A27: 合 计 | G27: =SUM(G7:G26) | K27: =SUM(K7:K26) | N27: =SUM(N7:N26) | O27: =IF(K27=0,"",(N27-K27)/K27*100)
A28: =封面!D11&封面!G11 | K28: ="评估人员："&封面!G20
A29: =CONCATENATE(封面!D13,封面!F13,封面!G13,封面!H13,封面!I13,封面!J13,封面!K13)

Sheet 产成品（库存商品）
A1: 返回索引页 | B1: 返回
A2: 存货—产成品（库存商品）评估明细表
A3: =CONCATENATE(封面!D9,封面!F9,封面!G9,封面!H9,封面!I9,封面!J9,封面!K9)
A4: =封面!D7&封面!F7 | O4: 金额单位：人民币元
A5: 序号 | B5: 名称及规格型号 | C5: 计量单位 | D5: 审计前账面值 | G5: 审计调整 | H5: 账面价值 | K5: 评估价值 | N5: 增值率% | O5: 备注 | P5: 存放地点
D6: 数量 | E6: 单价 | F6: 金额 | H6: 数量 | I6: 单价 | J6: 金额 | K6: 实际数量 | L6: 单价 | M6: 金额
E7: =IF(D7=0,"",F7/D7) | N7: =IF(J7=0,"",(M7-J7)/J7*100)
E8: =IF(D8=0,"",F8/D8) | N8: =IF(J8=0,"",(M8-J8)/J8*100)
E9: =IF(D9=0,"",F9/D9) | N9: =IF(J9=0,"",(M9-J9)/J9*100)
E10: =IF(D10=0,"",F10/D10) | N10: =IF(J10=0,"",(M10-J10)/J10*100)
E11: =IF(D11=0,"",F11/D11) | N11: =IF(J11=0,"",(M11-J11)/J11*100)
E12: =IF(D12=0,"",F12/D12) | N12: =IF(J12=0,"",(M12-J12)/J12*100)
E13: =IF(D13=0,"",F13/D13) | N13: =IF(J13=0,"",(M13-J13)/J13*100)
E14: =IF(D14=0,"",F14/D14) | N14: =IF(J14=0,"",(M14-J14)/J14*100)
E15: =IF(D15=0,"",F15/D15) | N15: =IF(J15=0,"",(M15-J15)/J15*100)
E16: =IF(D16=0,"",F16/D16) | N16: =IF(J16=0,"",(M16-J16)/J16*100)
E17: =IF(D17=0,"",F17/D17) | N17: =IF(J17=0,"",(M17-J17)/J17*100)
E18: =IF(D18=0,"",F18/D18) | N18: =IF(J18=0,"",(M18-J18)/J18*100)
... E25: =IF(D25=0,"",F25/D25) | N25: =IF(J25=0,"",(M25-J25)/J25*100)
A27: 合 计 | F27: =SUM(F7:F26) | J27: =SUM(J7:J26) | M27: =SUM(M7:M26) | N27: =IF(J27=0,"",(M27-J27)/J27*100)
A28: =封面!D11&封面!G11 | J28: ="评估人员："&封面!G20
A29: =CONCATENATE(封面!D13,封面!F13,封面!G13,封面!H13,封面!I13,封面!J13,封面!K13)
B30: 注1： | C30: 1）正常，无需填写；2）残次，填“A”；3）变质，填“B”；4）毁损，填“C”；5）滞销，填“E”；
C31: 6）积压，填“D”并在备注中填写已积压时间“1年以内”、“1~2年”、“2~3年”、“3年以上”；7）其他情形用文字表述。

Sheet 在产品（自制半成品）
A1: 返回索引页 | B1: 返回
A2: 存货—在产品（自制半成品）评估明细表
A3: =CONCATENATE(封面!D9,封面!F9,封面!G9,封面!H9,封面!I9,封面!J9,封面!K9)
A4: =封面!D7&封面!F7 | O4: 金额单位：人民币元
A5: 序号 | B5: 名称及规格型号 | C5: 计量单位 | D5: 审计前账面值 | G5: 审计调整 | H5: 账面价值 | K5: 评估价值 | N5: 增值率% | O5: 备注
D6: 数量 | E6: 单价 | F6: 金额 | H6: 数量 | I6: 单价 | J6: 金额 | K6: 实际数量 | L6: 单价 | M6: 金额
E7: =IF(D7=0,"",F7/D7) | N7: =IF(J7=0,"",(M7-J7)/J7*100)
E8: =IF(D8=0,"",F8/D8) | N8: =IF(J8=0,"",(M8-J8)/J8*100)
E9: =IF(D9=0,"",F9/D9) | N9: =IF(J9=0,"",(M9-J9)/J9*100)
E10: =IF(D10=0,"",F10/D10) | N10: =IF(J10=0,"",(M10-J10)/J10*100)
E11: =IF(D11=0,"",F11/D11) | N11: =IF(J11=0,"",(M11-J11)/J11*100)
E12: =IF(D12=0,"",F12/D12) | N12: =IF(J12=0,"",(M12-J12)/J12*100)
E13: =IF(D13=0,"",F13/D13) | N13: =IF(J13=0,"",(M13-J13)/J13*100)
E14: =IF(D14=0,"",F14/D14) | N14: =IF(J14=0,"",(M14-J14)/J14*100)
E15: =IF(D15=0,"",F15/D15) | N15: =IF(J15=0,"",(M15-J15)/J15*100)
E16: =IF(D16=0,"",F16/D16) | N16: =IF(J16=0,"",(M16-J16)/J16*100)
E17: =IF(D17=0,"",F17/D17) | N17: =IF(J17=0,"",(M17-J17)/J17*100)
E18: =IF(D18=0,"",F18/D18) | N18: =IF(J18=0,"",(M18-J18)/J18*100)
... E25: =IF(D25=0,"",F25/D25) | N25: =IF(J25=0,"",(M25-J25)/J25*100)
A27: 合 计 | F27: =SUM(F7:F26) | J27: =SUM(J7:J26) | M27: =SUM(M7:M26) | N27: =IF(J27=0,"",(M27-J27)/J27*100)
A28: =封面!D11&封面!G11 | J28: ="评估人员："&封面!G20
A29: =CONCATENATE(封面!D13,封面!F13,封面!G13,封面!H13,封面!I13,封面!J13,封面!K13)

Sheet 发出商品
A1: 返回索引页 | B1: 返回
A2: 存货—发出商品评估明细表
A3: =CONCATENATE(封面!D9,封面!F9,封面!G9,封面!H9,封面!I9,封面!J9,封面!K9)
A4: =封面!D7&封面!F7 | P4: 金额单位：人民币元
A5: 序号 | B5: 商品名称 | C5: 对方单位名称 | D5: 计量单位 | E5: 审计前账面值 | H5: 审计调整 | I5: 账面价值 | L5: 评估价值 | O5: 增值率% | P5: 备注
E6: 数量 | F6: 单价 | G6: 金额 | I6: 数量 | J6: 单价 | K6: 金额 | L6: 实际数量 | M6: 单价 | N6: 金额 | W6: 税金及附加率 | X6: 销售费用率 | Y6: 营业利润率 | Z6: 所得税率 | AA6: 净利润率 | AB6: R | AC6: 评估单价
O7: =IF(K7=0,"",(N7-K7)/K7*100) | V7: =J7*(1+$AH$19) | W7: =AI14 | X7: =AI15 | Y7: =AI16 | AA7: =AI17 | AC7: =V7*(1-$W$7-$X$7-$Y$7*$Z$7-$AA$7*$AB$7) | AH7: 毛利率采用加权平均数计算=[（A1-B1）+(A23-B2)]/(A1+A2)
O8: =IF(K8=0,"",(N8-K8)/K8*100) | V8: =J8*(1+$AH$19) | AC8: =V8*(1-$W$7-$X$7-$Y$7*$Z$7-$AA$7*$AB$7)
O9: =IF(K9=0,"",(N9-K9)/K9*100) | V9: =J9*(1+$AH$19) | AC9: =V9*(1-$W$7-$X$7-$Y$7*$Z$7-$AA$7*$AB$7) | AD9: A | AE9: 营业收入 | AH9: =AF9+AG9
O10: =IF(K10=0,"",(N10-K10)/K10*100) | V10: =J10*(1+$AH$19) | AC10: =V10*(1-$W$7-$X$7-$Y$7*$Z$7-$AA$7*$AB$7) | AE10: 营业税金及附加
O11: =IF(K11=0,"",(N11-K11)/K11*100) | V11: =J11*(1+$AH$19) | AC11: =V11*(1-$W$7-$X$7-$Y$7*$Z$7-$AA$7*$AB$7) | AE11: 销售费用
O12: =IF(K12=0,"",(N12-K12)/K12*100) | V12: =J12*(1+$AH$19) | AC12: =V12*(1-$W$7-$X$7-$Y$7*$Z$7-$AA$7*$AB$7) | AE12: 营业利润
O13: =IF(K13=0,"",(N13-K13)/K13*100) | V13: =J13*(1+$AH$19) | AC13: =V13*(1-$W$7-$X$7-$Y$7*$Z$7-$AA$7*$AB$7) | AE13: 净利润
O14: =IF(K14=0,"",(N14-K14)/K14*100) | V14: =J14*(1+$AH$19) | AC14: =V14*(1-$W$7-$X$7-$Y$7*$Z$7-$AA$7*$AB$7) | AE14: 税金及附加率 | AF14: =AF10/AF9 | AG14: =AG10/AG9 | AI14: =(AF14+AG14+AH14)/2
O15: =IF(K15=0,"",(N15-K15)/K15*100) | V15: =J15*(1+$AH$19) | AC15: =V15*(1-$W$7-$X$7-$Y$7*$Z$7-$AA$7*$AB$7) | AE15: 销售费用率 | AF15: =AF11/AF9 | AG15: =AG11/AG9 | AI15: =(AF15+AG15+AH15)/2
O16: =IF(K16=0,"",(N16-K16)/K16*100) | V16: =J16*(1+$AH$19) | AC16: =V16*(1-$W$7-$X$7-$Y$7*$Z$7-$AA$7*$AB$7) | AE16: 营业利润率 | AF16: =AF12/AF9 | AG16: =AG12/AG9 | AI16: =(AF16+AG16+AH16)/2
O17: =IF(K17=0,"",(N17-K17)/K17*100) | V17: =J17*(1+$AH$19) | AC17: =V17*(1-$W$7-$X$7-$Y$7*$Z$7-$AA$7*$AB$7) | AE17: 净利润率 | AF17: =AF13/AF9 | AG17: =AG13/AG9 | AI17: =(AF17+AG17+AH17)/2
O18: =IF(K18=0,"",(N18-K18)/K18*100) | V18: =J18*(1+$AH$19) | AC18: =V18*(1-$W$7-$X$7-$Y$7*$Z$7-$AA$7*$AB$7) | AD18: B | AE18: 营业成本 | AH18: =AF18+AG18
O19: =IF(K19=0,"",(N19-K19)/K19*100) | V19: =J19*(1+$AH$19) | AC19: =V19*(1-$W$7-$X$7-$Y$7*$Z$7-$AA$7*$AB$7) | AF19: =(AF9-AF18)/AF9 | AG19: =(AG9-AG18)/AG9 | AH19: =0.3
O20: =IF(K20=0,"",(N20-K20)/K20*100) | V20: =J20*(1+$AH$19) | AC20: =V20*(1-$W$7-$X$7-$Y$7*$Z$7-$AA$7*$AB$7)
O21: =IF(K21=0,"",(N21-K21)/K21*100) | V21: =J21*(1+$AH$19) | AC21: =V21*(1-$W$7-$X$7-$Y$7*$Z$7-$AA$7*$AB$7)
O22: =IF(K22=0,"",(N22-K22)/K22*100) | V22: =J22*(1+$AH$19) | AC22: =V22*(1-$W$7-$X$7-$Y$7*$Z$7-$AA$7*$AB$7)
O23: =IF(K23=0,"",(N23-K23)/K23*100) | V23: =J23*(1+$AH$19) | AC23: =V23*(1-$W$7-$X$7-$Y$7*$Z$7-$AA$7*$AB$7)
O24: =IF(K24=0,"",(N24-K24)/K24*100) | V24: =J24*(1+$AH$19) | AC24: =V24*(1-$W$7-$X$7-$Y$7*$Z$7-$AA$7*$AB$7)
O25: =IF(K25=0,"",(N25-K25)/K25*100) | V25: =J25*(1+$AH$19) | AC25: =V25*(1-$W$7-$X$7-$Y$7*$Z$7-$AA$7*$AB$7)
O26: =IF(K26=0,"",(N26-K26)/K26*100) | V26: =J26*(1+$AH$19) | AC26: =V26*(1-$W$7-$X$7-$Y$7*$Z$7-$AA$7*$AB$7)
O27: =IF(K27=0,"",(N27-K27)/K27*100) | V27: =J27*(1+$AH$19) | AC27: =V27*(1-$W$7-$X$7-$Y$7*$Z$7-$AA$7*$AB$7)
O28: =IF(K28=0,"",(N28-K28)/K28*100) | V28: =J28*(1+$AH$19) | AC28: =V28*(1-$W$7-$X$7-$Y$7*$Z$7-$AA$7*$AB$7)
O29: =IF(K29=0,"",(N29-K29)/K29*100) | V29: =J29*(1+$AH$19) | AC29: =V29*(1-$W$7-$X$7-$Y$7*$Z$7-$AA$7*$AB$7)
O30: =IF(K30=0,"",(N30-K30)/K30*100) | V30: =J30*(1+$AH$19) | AC30: =V30*(1-$W$7-$X$7-$Y$7*$Z$7-$AA$7*$AB$7)
O31: =IF(K31=0,"",(N31-K31)/K31*100) | V31: =J31*(1+$AH$19) | AC31: =V31*(1-$W$7-$X$7-$Y$7*$Z$7-$AA$7*$AB$7)
... O34: =IF(K34=0,"",(N34-K34)/K34*100) | V34: =J34*(1+$AH$19) | AC34: =V34*(1-$W$7-$X$7-$Y$7*$Z$7-$AA$7*$AB$7)
F35: =IF(E35=0,"",G35/E35) | O35: =IF(K35=0,"",(N35-K35)/K35*100) | V35: =J36
V36: =J37
A37: 合 计 | G37: =SUM(G7:G36) | V37: =J38
A38: =封面!D11&封面!G11 | K38: ="评估人员："&封面!G20 | V38: =J39
A39: =CONCATENATE(封面!D13,封面!F13,封面!G13,封面!H13,封面!I13,封面!J13,封面!K13) | V39: =J40
V40: =J41
V41: =J42
V42: =J43
...

Sheet 在用周转材料
A1: 返回索引页 | B1: 返回
A2: 存货—在用周转材料评估明细表
A3: =CONCATENATE(封面!D9,封面!F9,封面!G9,封面!H9,封面!I9,封面!J9,封面!K9)
A4: =封面!D7&封面!F7 | P4: 金额单位：人民币元
A5: 序号 | B5: 名称及规格型号 | C5: 启用日期 | D5: 原始入账价值 | E5: 计量单位 | F5: 审计前账面值 | H5: 审计调整 | I5: 账面价值 | K5: 实际数量 | L5: 评估价值 | O5: 增值率% | P5: 备注
F6: 数量 | G6: 金额 | I6: 数量 | J6: 金额 | L6: 单价 | M6: 成新率% | N6: 金额
N7: =K7*L7*M7/100 | O7: =IF(J7=0,"",(N7-J7)/J7*100)
N8: =K8*L8*M8/100 | O8: =IF(J8=0,"",(N8-J8)/J8*100)
N9: =K9*L9*M9/100 | O9: =IF(J9=0,"",(N9-J9)/J9*100)
N10: =K10*L10*M10/100 | O10: =IF(J10=0,"",(N10-J10)/J10*100)
N11: =K11*L11*M11/100 | O11: =IF(J11=0,"",(N11-J11)/J11*100)
N12: =K12*L12*M12/100 | O12: =IF(J12=0,"",(N12-J12)/J12*100)
N13: =K13*L13*M13/100 | O13: =IF(J13=0,"",(N13-J13)/J13*100)
N14: =K14*L14*M14/100 | O14: =IF(J14=0,"",(N14-J14)/J14*100)
N15: =K15*L15*M15/100 | O15: =IF(J15=0,"",(N15-J15)/J15*100)
N16: =K16*L16*M16/100 | O16: =IF(J16=0,"",(N16-J16)/J16*100)
N17: =K17*L17*M17/100 | O17: =IF(J17=0,"",(N17-J17)/J17*100)
N18: =K18*L18*M18/100 | O18: =IF(J18=0,"",(N18-J18)/J18*100)
... N25: =K25*L25*M25/100 | O25: =IF(J25=0,"",(N25-J25)/J25*100)
A27: 合 计 | G27: =SUM(G7:G26) | J27: =SUM(J7:J26) | N27: =SUM(N7:N26) | O27: =IF(J27=0,"",(N27-J27)/J27*100)
A28: =封面!D11&封面!G11 | J28: ="评估人员："&封面!G20
A29: =CONCATENATE(封面!D13,封面!F13,封面!G13,封面!H13,封面!I13,封面!J13,封面!K13)

Sheet 一年到期非流动资产
A1: 返回索引页 | B1: 返回
A2: 一年内到期的非流动资产评估明细表
A3: =CONCATENATE(封面!D9,封面!F9,封面!G9,封面!H9,封面!I9,封面!J9,封面!K9)
A4: =封面!D7&封面!F7 | J4: 金额单位：人民币元
A5: 序号 | B5: 项目及内容 | C5: 发生日期 | D5: 结算内容 | E5: 审计前账面值 | F5: 审计调整 | G5: 账面价值 | H5: 评估价值 | I5: 增值率% | J5: 备注
I6: =IF(G6=0,"",(H6-G6)/G6*100)
I7: =IF(G7=0,"",(H7-G7)/G7*100)
I8: =IF(G8=0,"",(H8-G8)/G8*100)
I9: =IF(G9=0,"",(H9-G9)/G9*100)
I10: =IF(G10=0,"",(H10-G10)/G10*100)
I11: =IF(G11=0,"",(H11-G11)/G11*100)
I12: =IF(G12=0,"",(H12-G12)/G12*100)
I13: =IF(G13=0,"",(H13-G13)/G13*100)
I14: =IF(G14=0,"",(H14-G14)/G14*100)
I15: =IF(G15=0,"",(H15-G15)/G15*100)
I16: =IF(G16=0,"",(H16-G16)/G16*100)
I17: =IF(G17=0,"",(H17-G17)/G17*100)
... I25: =IF(G25=0,"",(H25-G25)/G25*100)
A27: 合 计 | E27: =SUM(E6:E26) | G27: =SUM(G6:G26) | H27: =SUM(H6:H26) | I27: =IF(G27=0,"",(H27-G27)/G27*100)
A28: =封面!D11&封面!G11 | G28: ="评估人员："&封面!G20
A29: =CONCATENATE(封面!D13,封面!F13,封面!G13,封面!H13,封面!I13,封面!J13,封面!K13)

Sheet 其他流动资产
A1: 返回索引页 | B1: 返回
A2: 其他流动资产评估明细表
A3: =CONCATENATE(封面!D9,封面!F9,封面!G9,封面!H9,封面!I9,封面!J9,封面!K9)
A4: =封面!D7&封面!F7 | J4: 金额单位：人民币元
A5: 序号 | B5: 项目及内容 | C5: 发生日期 | D5: 结算内容 | E5: 审计前账面值 | F5: 审计调整 | G5: 账面价值 | H5: 评估价值 | I5: 增值率% | J5: 备注
I6: =IF(G6=0,"",(H6-G6)/G6*100)
I7: =IF(G7=0,"",(H7-G7)/G7*100)
I8: =IF(G8=0,"",(H8-G8)/G8*100)
I9: =IF(G9=0,"",(H9-G9)/G9*100)
I10: =IF(G10=0,"",(H10-G10)/G10*100)
I11: =IF(G11=0,"",(H11-G11)/G11*100)
I12: =IF(G12=0,"",(H12-G12)/G12*100)
I13: =IF(G13=0,"",(H13-G13)/G13*100)
I14: =IF(G14=0,"",(H14-G14)/G14*100)
I15: =IF(G15=0,"",(H15-G15)/G15*100)
I16: =IF(G16=0,"",(H16-G16)/G16*100)
I17: =IF(G17=0,"",(H17-G17)/G17*100)
... I25: =IF(G25=0,"",(H25-G25)/G25*100)
A27: 合 计 | E27: =SUM(E6:E26) | G27: =SUM(G6:G26) | H27: =SUM(H6:H26) | I27: =IF(G27=0,"",(H27-G27)/G27*100)
A28: =封面!D11&封面!G11 | G28: ="评估人员："&封面!G20
A29: =CONCATENATE(封面!D13,封面!F13,封面!G13,封面!H13,封面!I13,封面!J13,封面!K13)

Sheet 非流动资产汇总
A1: 返回索引页 | B1: 返回
A2: 非流动资产评估汇总表
A3: =CONCATENATE(封面!D9,封面!F9,封面!G9,封面!H9,封面!I9,封面!J9,封面!K9)
A4: =封面!D7&封面!F7 | G4: 金额单位：人民币元
A5: 编号 | B5: 科目名称 | C5: 审计前账面值 | D5: 账面价值 | E5: 评估价值 | F5: 增值额 | G5: 增值率%
A6: 4-1 | B6: 可供出售金融资产 | C6: =可供出售金融资产汇总!C27 | D6: =可供出售金融资产汇总!E27 | E6: =可供出售金融资产汇总!F27 | F6: =E6-D6 | G6: =IF(D6=0,"",F6/D6*100)
A7: 4-2 | B7: 持有至到期投资 | C7: =持有到期投资!H27 | D7: =持有到期投资!J27 | E7: =持有到期投资!K27 | F7: =E7-D7 | G7: =IF(D7=0,"",F7/D7*100)
A8: 4-3 | B8: 长期应收款 | C8: =长期应收!E27 | D8: =长期应收!G27 | E8: =长期应收!H27 | F8: =E8-D8 | G8: =IF(D8=0,"",F8/D8*100)
A9: 4-4 | B9: 长期股权投资 | C9: =股权投资!G27 | D9: =股权投资!I27 | E9: =股权投资!J27 | F9: =E9-D9 | G9: =IF(D9=0,"",F9/D9*100)
A10: 4-5 | B10: 投资性房地产 | C10: ='4-5-1投资性房地产'!K27+'4-5-2投资性房地产'!L27+'4-5-3投资性地产'!M27+'4-5-4投资性地产'!M27 | D10: ='4-5-1投资性房地产'!O27+'4-5-2投资性房地产'!N27+'4-5-3投资性地产'!O27+'4-5-4投资性地产'!O27 | E10: ='4-5-1投资性房地产'!R27+'4-5-2投资性房地产'!O27+'4-5-3投资性地产'!P27+'4-5-4投资性地产'!P27 | F10: =E10-D10 | G10: =IF(D10=0,"",F10/D10*100)
A11: 4-6 | B11: 固定资产 | C11: =固定资产汇总!D22 | D11: =固定资产汇总!F22 | E11: =固定资产汇总!H22 | F11: =E11-D11 | G11: =IF(D11=0,"",F11/D11*100)
A12: 4-7 | B12: 在建工程 | C12: =在建工程汇总!C27 | D12: =在建工程汇总!D27 | E12: =在建工程汇总!E27 | F12: =E12-D12 | G12: =IF(D12=0,"",F12/D12*100)
A13: 4-8 | B13: 工程物资 | C13: =工程物资!G27 | D13: =工程物资!K27 | E13: =工程物资!N27 | F13: =E13-D13 | G13: =IF(D13=0,"",F13/D13*100)
A14: 4-9 | B14: 固定资产清理 | C14: =固定资产清理!D27 | D14: =固定资产清理!F27 | E14: =固定资产清理!G27 | F14: =E14-D14 | G14: =IF(D14=0,"",F14/D14*100)
A15: 4-10 | B15: 生产性生物资产 | C15: =生产性生物资产!I27 | D15: =生产性生物资产!M27 | E15: =生产性生物资产!P27 | F15: =E15-D15 | G15: =IF(D15=0,"",F15/D15*100)
A16: 4-11 | B16: 油气资产 | C16: =油气资产!J27 | D16: =油气资产!N27 | E16: =油气资产!Q27 | F16: =E16-D16 | G16: =IF(D16=0,"",F16/D16*100)
A17: 4-12 | B17: 使用权资产 | D17: =使用权资产!H27 | E17: =使用权资产!J27 | F17: =使用权资产!K27
A18: 4-13 | B18: 无形资产 | C18: =无形资产汇总!C27 | D18: =无形资产汇总!D27 | E18: =无形资产汇总!E27 | F18: =E18-D18 | G18: =IF(D18=0,"",F18/D18*100)
A19: 4-14 | B19: 开发支出 | C19: =开发支出!D27 | D19: =开发支出!F27 | E19: =开发支出!G27 | F19: =E19-D19 | G19: =IF(D19=0,"",F19/D19*100)
A20: 4-15 | B20: 商誉 | C20: =商誉!D27 | D20: =商誉!F27 | E20: =商誉!G27 | F20: =E20-D20 | G20: =IF(D20=0,"",F20/D20*100)
A21: 4-16 | B21: 长期待摊费用 | C21: =长期待摊费用!F27 | D21: =长期待摊费用!H27 | E21: =长期待摊费用!J27 | F21: =E21-D21 | G21: =IF(D21=0,"",F21/D21*100)
A22: 4-17 | B22: 递延所得税资产 | C22: =递延所得税资产!D27 | D22: =递延所得税资产!F27 | E22: =递延所得税资产!G27 | F22: =E22-D22 | G22: =IF(D22=0,"",F22/D22*100)
A23: 4-18 | B23: 其他非流动资产 | C23: =其他非流动资产!D27 | D23: =其他非流动资产!F27 | E23: =其他非流动资产!G27 | F23: =E23-D23 | G23: =IF(D23=0,"",F23/D23*100)
A28: 4 | B28: 合计 | C28: =SUM(C6:C27) | D28: =SUM(D6:D27) | E28: =SUM(E6:E27) | F28: =SUM(F6:F27) | G28: =IF(D28=0,"",F28/D28*100)
A29: =封面!D11&封面!G11 | E29: ="评估人员："&封面!G22
A30: =CONCATENATE(封面!D13,封面!F13,封面!G13,封面!H13,封面!I13,封面!J13,封面!K13)
D32: =D11/10000 | E32: =E11/10000 | F32: =F11/10000
D33: =D18/10000 | E33: =E18/10000 | F33: =F18/10000
D34: =D28/10000 | E34: =E28/10000 | F34: =F28/10000

Sheet 可供出售金融资产汇总
A1: 返回索引页 | B1: 返回
A2: 可供出售金融资产评估汇总表
A3: =CONCATENATE(封面!D9,封面!F9,封面!G9,封面!H9,封面!I9,封面!J9,封面!K9)
A4: =封面!D7&封面!F7 | H4: 金额单位：人民币元
A5: 编号 | B5: 科目名称 | C5: 审计前账面值 | D5: 审计调整 | E5: 账面价值 | F5: 评估价值 | G5: 增值额 | H5: 增值率%
A6: 4-1-1 | B6: 可供出售金融资产-股票投资 | C6: ='可出售-股票'!I27 | E6: ='可出售-股票'!K27 | F6: ='可出售-股票'!L27 | G6: =F6-E6 | H6: =IF(E6=0,"",G6/E6*100)
A7: 4-1-2 | B7: 可供出售金融资产-债券投资 | C7: ='可出售-债券'!H27 | E7: ='可出售-债券'!J27 | F7: ='可出售-债券'!K27 | G7: =F7-E7 | H7: =IF(E7=0,"",G7/E7*100)
A8: 4-1-3 | B8: 可供出售金融资产-其他投资 | C8: ='可出售-其他'!H27 | E8: ='可出售-其他'!J27 | F8: ='可出售-其他'!K27 | G8: =F8-E8 | H8: =IF(E8=0,"",G8/E8*100)
A25: 4 | B25: 可供出售金融资产合计 | C25: =SUM(C6:C24) | E25: =SUM(E6:E24) | F25: =SUM(F6:F24) | G25: =SUM(G6:G24) | H25: =IF(E25=0,"",G25/E25*100)
A26: 4 | B26: 减：可供出售金融资产减值准备 | E26: =C26 | F26: 0 | G26: =F26-E26 | H26: =IF(E26=0,"",G26/E26*100)
A27: 4 | B27: 可供出售金融资产净额 | C27: =C25-C26 | E27: =E25-E26 | F27: =F25-F26 | G27: =G25-G26 | H27: =IF(E27=0,"",G27/E27*100)
A28: =封面!D11&封面!G11 | F28: ="评估人员："&封面!G22
A29: =CONCATENATE(封面!D13,封面!F13,封面!G13,封面!H13,封面!I13,封面!J13,封面!K13)

Sheet 可出售-股票
A1: 返回索引页 | B1: 返回
A2: 可供出售金融资产—股票投资评估明细表
A3: =CONCATENATE(封面!D9,封面!F9,封面!G9,封面!H9,封面!I9,封面!J9,封面!K9)
A4: =封面!D7&封面!F7 | N4: 金额单位：人民币元
A5: 序号 | B5: 被投资单位名称 | C5: 股票性质 | D5: 投资日期 | E5: 持股数量 | F5: 持股比例% | G5: 基准日市价 | H5: 取得成本 | I5: 审计前账面值 | J5: 审计调整 | K5: 账面价值 | L5: 评估价值 | M5: 增值率% | N5: 备注
M6: =IF(K6=0,"",(L6-K6)/K6*100)
M7: =IF(K7=0,"",(L7-K7)/K7*100)
M8: =IF(K8=0,"",(L8-K8)/K8*100)
M9: =IF(K9=0,"",(L9-K9)/K9*100)
M10: =IF(K10=0,"",(L10-K10)/K10*100)
M11: =IF(K11=0,"",(L11-K11)/K11*100)
M12: =IF(K12=0,"",(L12-K12)/K12*100)
M13: =IF(K13=0,"",(L13-K13)/K13*100)
M14: =IF(K14=0,"",(L14-K14)/K14*100)
M15: =IF(K15=0,"",(L15-K15)/K15*100)
M16: =IF(K16=0,"",(L16-K16)/K16*100)
M17: =IF(K17=0,"",(L17-K17)/K17*100)
... M25: =IF(K25=0,"",(L25-K25)/K25*100)
A27: 合 计 | I27: =SUM(I6:I26) | K27: =SUM(K6:K26) | L27: =SUM(L6:L26) | M27: =IF(K27=0,"",(L27-K27)/K27*100)
A28: =封面!D11&封面!G11 | K28: ="评估人员："&封面!G22
A29: =CONCATENATE(封面!D13,封面!F13,封面!G13,封面!H13,封面!I13,封面!J13,封面!K13)

Sheet 可出售-债券
A1: 返回索引页 | B1: 返回
A2: 可供出售金融资产—债券投资评估明细表
A3: =CONCATENATE(封面!D9,封面!F9,封面!G9,封面!H9,封面!I9,封面!J9,封面!K9)
A4: =封面!D7&封面!F7 | M4: 金额单位：人民币元
A5: 序号 | B5: 被投资单位名称 | C5: 债券种类 | D5: 发行日期 | E5: 到期日 | F5: 票面利率% | G5: 成本（面值） | H5: 审计前账面值 | I5: 审计调整 | J5: 账面价值 | K5: 评估价值 | L5: 增值率% | M5: 备注
L6: =IF(J6=0,"",(K6-J6)/J6*100)
L7: =IF(J7=0,"",(K7-J7)/J7*100)
L8: =IF(J8=0,"",(K8-J8)/J8*100)
L9: =IF(J9=0,"",(K9-J9)/J9*100)
L10: =IF(J10=0,"",(K10-J10)/J10*100)
L11: =IF(J11=0,"",(K11-J11)/J11*100)
L12: =IF(J12=0,"",(K12-J12)/J12*100)
L13: =IF(J13=0,"",(K13-J13)/J13*100)
L14: =IF(J14=0,"",(K14-J14)/J14*100)
L15: =IF(J15=0,"",(K15-J15)/J15*100)
L16: =IF(J16=0,"",(K16-J16)/J16*100)
L17: =IF(J17=0,"",(K17-J17)/J17*100)
... L25: =IF(J25=0,"",(K25-J25)/J25*100)
A27: 合 计 | H27: =SUM(H6:H26) | J27: =SUM(J6:J26) | K27: =SUM(K6:K26) | L27: =IF(J27=0,"",(K27-J27)/J27*100)
A28: =封面!D11&封面!G11 | J28: ="评估人员："&封面!G22
A29: =CONCATENATE(封面!D13,封面!F13,封面!G13,封面!H13,封面!I13,封面!J13,封面!K13)

Sheet 可出售-其他
A1: 返回索引页 | B1: 返回
A2: 可供出售金融资产—其他投资评估明细表
A3: =CONCATENATE(封面!D9,封面!F9,封面!G9,封面!H9,封面!I9,封面!J9,封面!K9)
A4: =封面!D7&封面!F7 | M4: 金额单位：人民币元
A5: 序号 | B5: 被投资单位名称 | C5: 金融资产名称 | D5: 投资日期 | E5: 持有数量 | F5: 基准日市价 | G5: 成本 | H5: 审计前账面值 | I5: 审计调整 | J5: 账面价值 | K5: 评估价值 | L5: 增值率% | M5: 备注
L6: =IF(J6=0,"",(K6-J6)/J6*100)
L7: =IF(J7=0,"",(K7-J7)/J7*100)
L8: =IF(J8=0,"",(K8-J8)/J8*100)
L9: =IF(J9=0,"",(K9-J9)/J9*100)
L10: =IF(J10=0,"",(K10-J10)/J10*100)
L11: =IF(J11=0,"",(K11-J11)/J11*100)
L12: =IF(J12=0,"",(K12-J12)/J12*100)
L13: =IF(J13=0,"",(K13-J13)/J13*100)
L14: =IF(J14=0,"",(K14-J14)/J14*100)
L15: =IF(J15=0,"",(K15-J15)/J15*100)
L16: =IF(J16=0,"",(K16-J16)/J16*100)
L17: =IF(J17=0,"",(K17-J17)/J17*100)
... L25: =IF(J25=0,"",(K25-J25)/J25*100)
A27: 合 计 | H27: =SUM(H6:H26) | J27: =SUM(J6:J26) | K27: =SUM(K6:K26) | L27: =IF(J27=0,"",(K27-J27)/J27*100)
A28: =封面!D11&封面!G11 | J28: ="评估人员："&封面!G22
A29: =CONCATENATE(封面!D13,封面!F13,封面!G13,封面!H13,封面!I13,封面!J13,封面!K13)

Sheet 持有到期投资
A1: 返回索引页 | B1: 返回
A2: 持有至到期投资评估明细表
A3: =CONCATENATE(封面!D9,封面!F9,封面!G9,封面!H9,封面!I9,封面!J9,封面!K9)
A4: =封面!D7&封面!F7 | M4: 金额单位：人民币元
A5: 序号 | B5: 被投资单位名称 | C5: 投资类别 | D5: 投资日期 | E5: 到期日 | F5: 票面利率% | G5: 投资成本 | H5: 审计前账面值 | I5: 审计调整 | J5: 账面价值 | K5: 评估价值 | L5: 增值率% | M5: 备注
L6: =IF(J6=0,"",(K6-J6)/J6*100)
L7: =IF(J7=0,"",(K7-J7)/J7*100)
L8: =IF(J8=0,"",(K8-J8)/J8*100)
L9: =IF(J9=0,"",(K9-J9)/J9*100)
L10: =IF(J10=0,"",(K10-J10)/J10*100)
L11: =IF(J11=0,"",(K11-J11)/J11*100)
L12: =IF(J12=0,"",(K12-J12)/J12*100)
L13: =IF(J13=0,"",(K13-J13)/J13*100)
L14: =IF(J14=0,"",(K14-J14)/J14*100)
L15: =IF(J15=0,"",(K15-J15)/J15*100)
L16: =IF(J16=0,"",(K16-J16)/J16*100)
L17: =IF(J17=0,"",(K17-J17)/J17*100)
... L24: =IF(J24=0,"",(K24-J24)/J24*100)
A25: 合 计 | H25: =SUM(H6:H24) | J25: =SUM(J6:J24) | K25: =SUM(K6:K24) | L25: =IF(J25=0,"",(K25-J25)/J25*100)
A26: 减：持有至到期投资减值准备 | J26: =H26 | L26: =IF(J26=0,"",(K26-J26)/J26*100)
A27: 净 额 | H27: =H25-H26 | J27: =J25-J26 | K27: =K25-K26 | L27: =IF(J27=0,"",(K27-J27)/J27*100)
A28: =封面!D11&封面!G11 | J28: ="评估人员："&封面!G22
A29: =CONCATENATE(封面!D13,封面!F13,封面!G13,封面!H13,封面!I13,封面!J13,封面!K13)

Sheet 长期应收
A1: 返回索引页 | B1: 返回
A2: 长期应收款评估明细表
A3: =CONCATENATE(封面!D9,封面!F9,封面!G9,封面!H9,封面!I9,封面!J9,封面!K9)
A4: =封面!D7&封面!F7 | J4: 金额单位：人民币元
A5: 序号 | B5: 欠款单位名称（结算对象） | C5: 业务内容 | D5: 发生日期 | E5: 审计前账面值 | F5: 审计调整 | G5: 账面价值 | H5: 评估价值 | I5: 增值率% | J5: 备注
H6: =G6 | I6: =IF(G6=0,"",(H6-G6)/G6*100)
I7: =IF(G7=0,"",(H7-G7)/G7*100)
I8: =IF(G8=0,"",(H8-G8)/G8*100)
I9: =IF(G9=0,"",(H9-G9)/G9*100)
I10: =IF(G10=0,"",(H10-G10)/G10*100)
I11: =IF(G11=0,"",(H11-G11)/G11*100)
I12: =IF(G12=0,"",(H12-G12)/G12*100)
I13: =IF(G13=0,"",(H13-G13)/G13*100)
I14: =IF(G14=0,"",(H14-G14)/G14*100)
I15: =IF(G15=0,"",(H15-G15)/G15*100)
I16: =IF(G16=0,"",(H16-G16)/G16*100)
I17: =IF(G17=0,"",(H17-G17)/G17*100)
I18: =IF(G18=0,"",(H18-G18)/G18*100)
... I23: =IF(G23=0,"",(H23-G23)/G23*100)
A24: 合 计 | E24: =SUM(E6:E23) | G24: =SUM(G6:G23) | H24: =SUM(H6:H23) | I24: =IF(G24=0,"",(H24-G24)/G24*100)
A25: 减：坏账准备 | G25: =E25 | I25: =IF(G25=0,"",(H25-G25)/G25*100)
A26: 减：评估风险损失 | I26: =IF(G26=0,"",(H26-G26)/G26*100)
A27: 净 额 | E27: =E24-E25-E26 | G27: =G24-G25-G26 | H27: =H24-H25-H26 | I27: =IF(G27=0,"",(H27-G27)/G27*100)
A28: =封面!D11&封面!G11 | G28: ="评估人员："&封面!G22
A29: =CONCATENATE(封面!D13,封面!F13,封面!G13,封面!H13,封面!I13,封面!J13,封面!K13)
B30: 注1： | C30: 注明账齡在一年以上的账款的可收回性，若有部分可能不能收回，请估计不能收回的金額，以供评估时作參考。
B31: 注2：“备注”栏填写方法： | C31: 1）欠款单位为关联方、总公司内部或本公司内部单位的，应在备注栏注明“关联方”、“总公司内部”、“内部单位”；
C32: 2） 涉诉款项应在备注中标明“涉诉”；
C33: 3）评估基准日后已部分或全部收回款项的，应注明日期及金额，如“2003年2月4日收回8,530.00元”；
C34: 4）填表单位认为其他应说明的事项

Sheet 股权投资
A1: 返回索引页 | B1: 返回
A2: 长期股权投资评估明细表
A3: =CONCATENATE(封面!D9,封面!F9,封面!G9,封面!H9,封面!I9,封面!J9,封面!K9)
A4: =封面!D7&封面!F7 | L4: 金额单位：人民币元
A5: 序号 | B5: 被投资单位名称 | C5: 投资日期 | D5: 协议投资期限 | E5: 持股比例% | F5: 投资成本 | G5: 审计前账面值 | H5: 审计调整 | I5: 账面价值 | J5: 评估价值 | K5: 增值率% | L5: 备注
K6: =IF(I6=0,"",(J6-I6)/I6*100)
K7: =IF(I7=0,"",(J7-I7)/I7*100)
K8: =IF(I8=0,"",(J8-I8)/I8*100)
K9: =IF(I9=0,"",(J9-I9)/I9*100)
K10: =IF(I10=0,"",(J10-I10)/I10*100)
K11: =IF(I11=0,"",(J11-I11)/I11*100)
K12: =IF(I12=0,"",(J12-I12)/I12*100)
K13: =IF(I13=0,"",(J13-I13)/I13*100)
K14: =IF(I14=0,"",(J14-I14)/I14*100)
K15: =IF(I15=0,"",(J15-I15)/I15*100)
K16: =IF(I16=0,"",(J16-I16)/I16*100)
